Workbook
Name ds: OFFSET(#REF!,0,0,COUNTA(#REF!)-1)
Name ds: OFFSET(#REF!,0,0,COUNTA(#REF!)-1)
Name ds: OFFSET(#REF!,0,0,COUNTA(#REF!)-1)
Name ds: OFFSET(#REF!,0,0,COUNTA(#REF!)-1)
Name ds: OFFSET(#REF!,0,0,COUNTA(#REF!)-1)
Name F: #N/A
Name GraphAA: OFFSET(#REF!,0,0,COUNTA(#REF!)-1)
Name GraphAA: OFFSET(#REF!,0,0,COUNTA(#REF!)-1)
Name GraphAA: OFFSET(#REF!,0,0,COUNTA(#REF!)-1)
Name GraphAA: OFFSET(#REF!,0,0,COUNTA(#REF!)-1)
Name GraphAA: OFFSET(#REF!,0,0,COUNTA(#REF!)-1)
Name GraphBB: OFFSET(#REF!,0,0,COUNTA(#REF!)-1)
Name GraphBB: OFFSET(#REF!,0,0,COUNTA(#REF!)-1)
Name GraphBB: OFFSET(#REF!,0,0,COUNTA(#REF!)-1)
Name GraphBB: OFFSET(#REF!,0,0,COUNTA(#REF!)-1)
Name GraphBB: OFFSET(#REF!,0,0,COUNTA(#REF!)-1)
Name GraphCC: OFFSET(#REF!,0,0,COUNTA(#REF!)-1)
Name GraphCC: OFFSET(#REF!,0,0,COUNTA(#REF!)-1)
Name GraphCC: OFFSET(#REF!,0,0,COUNTA(#REF!)-1)
Name GraphCC: OFFSET(#REF!,0,0,COUNTA(#REF!)-1)
Name GraphCC: OFFSET(#REF!,0,0,COUNTA(#REF!)-1)
Name GraphDD: OFFSET(#REF!,0,0,COUNTA(#REF!)-1)
Name GraphDD: OFFSET(#REF!,0,0,COUNTA(#REF!)-1)
Name GraphDD: OFFSET(#REF!,0,0,COUNTA(#REF!)-1)
Name GraphDD: OFFSET(#REF!,0,0,COUNTA(#REF!)-1)
Name GraphDD: OFFSET(#REF!,0,0,COUNTA(#REF!)-1)
Name GraphEE: OFFSET(#REF!,0,0,COUNTA(#REF!)-1)
Name GraphEE: OFFSET(#REF!,0,0,COUNTA(#REF!)-1)
Name GraphEE: OFFSET(#REF!,0,0,COUNTA(#REF!)-1)
Name GraphEE: OFFSET(#REF!,0,0,COUNTA(#REF!)-1)
Name GraphEE: OFFSET(#REF!,0,0,COUNTA(#REF!)-1)
Name GraphFF: OFFSET(#REF!,0,0,COUNTA(#REF!)-1)
Name GraphFF: OFFSET(#REF!,0,0,COUNTA(#REF!)-1)
Name GraphFF: OFFSET(#REF!,0,0,COUNTA(#REF!)-1)
Name GraphFF: OFFSET(#REF!,0,0,COUNTA(#REF!)-1)
Name GraphFF: OFFSET(#REF!,0,0,COUNTA(#REF!)-1)
Name GraphGG: OFFSET(#REF!,0,0,COUNTA(#REF!)-1)
Name GraphGG: OFFSET(#REF!,0,0,COUNTA(#REF!)-1)
Name GraphGG: OFFSET(#REF!,0,0,COUNTA(#REF!)-1)
Name GraphGG: OFFSET(#REF!,0,0,COUNTA(#REF!)-1)
Name GraphGG: OFFSET(#REF!,0,0,COUNTA(#REF!)-1)
Name GraphHH: OFFSET(#REF!,0,0,COUNTA(#REF!)-1)
Name GraphHH: OFFSET(#REF!,0,0,COUNTA(#REF!)-1)
Name GraphHH: OFFSET(#REF!,0,0,COUNTA(#REF!)-1)
Name GraphHH: OFFSET(#REF!,0,0,COUNTA(#REF!)-1)
Name GraphHH: OFFSET(#REF!,0,0,COUNTA(#REF!)-1)
Name GraphII: OFFSET(#REF!,0,0,COUNTA(#REF!)-1)
Name GraphII: OFFSET(#REF!,0,0,COUNTA(#REF!)-1)
Name GraphII: OFFSET(#REF!,0,0,COUNTA(#REF!)-1)
Name GraphII: OFFSET(#REF!,0,0,COUNTA(#REF!)-1)
Name GraphII: OFFSET(#REF!,0,0,COUNTA(#REF!)-1)
Name GraphJJ: OFFSET(#REF!,0,0,COUNTA(#REF!)-1)
Name GraphJJ: OFFSET(#REF!,0,0,COUNTA(#REF!)-1)
Name GraphJJ: OFFSET(#REF!,0,0,COUNTA(#REF!)-1)
Name GraphJJ: OFFSET(#REF!,0,0,COUNTA(#REF!)-1)
Name GraphJJ: OFFSET(#REF!,0,0,COUNTA(#REF!)-1)
Name GraphKK: OFFSET(#REF!,0,0,COUNTA(#REF!)-1)
Name GraphKK: OFFSET(#REF!,0,0,COUNTA(#REF!)-1)
Name GraphKK: OFFSET(#REF!,0,0,COUNTA(#REF!)-1)
Name GraphKK: OFFSET(#REF!,0,0,COUNTA(#REF!)-1)

Sheet IC&CF&BS
B1: איי.סי.אל (כימיקלים לישראל)
A2: רוה"ס | C2: FY 2024 | D2: FY 2023 | E2: FY 2022 | F2: FY 2021 | G2: FY 2020 | H2: FY 2019 | I2: FY 2018 | J2: FY 2017 | K2: FY 2016 | L2: FY 2015 | M2: FY 2014 | O2: Q2 2025 | P2: Q1 2025 | Q2: Q4 2024 | R2: Q3 2024 | S2: Q2 2024 | T2: Q1 2024 | U2: Q4 2023 | V2: Q3 2023 | W2: Q2 2023 | X2: Q1 2023 | Y2: Q4 2022 | Z2: Q3 2022 | AA2: Q2 2022 | AB2: Q1 2022 | AC2: Q4 2021 | AD2: Q3 2021 | AE2: Q2 2021 | AF2: Q1 2021 | AG2: Q4 2020 | AH2: Q3 2020 | AI2: Q2 2020 | AJ2: Q1 2020 | AK2: Q4 2019 | AL2: Q3 2019 | AM2: Q2 2019 | AN2: Q1 2019 | AO2: Q4 2018 | AP2: Q3 2018 | AQ2: Q2 2018 | AR2: Q1 2018
B3: הכנסות מביצוע עבודות, ממכירות וממתן שירותים | C3: 6841 | D3: 7536 | E3: 10015 | F3: 6955 | G3: 5043 | H3: 5271 | I3: 5556 | J3: 5418 | K3: 5363 | L3: 5405 | M3: 6111 | O3: 1832 | P3: 1767 | Q3: =C3-R3-S3-T3 -> 1601 | R3: 1753 | S3: 1752 | T3: 1735 | U3: =D3-V3-W3-X3 -> 1742 | V3: 1862 | W3: 1834 | X3: 2098 | Y3: =E3-Z3-AA3-AB3 -> 2091 | Z3: 2519 | AA3: 2880 | AB3: 2525 | AC3: =F3-AD3-AE3-AF3 -> 2038 | AD3: 1790 | AE3: 1617 | AF3: 1510 | AG3: =G3-AH3-AI3-AJ3 -> 1317 | AH3: 1204 | AI3: 1203 | AJ3: 1319 | AK3: =H3-AL3-AM3-AN3 -> 1106 | AL3: 1325 | AM3: 1425 | AN3: 1415 | AO3: =I3-AP3-AQ3-AR3 -> 1410 | AP3: 1371 | AQ3: 1371 | AR3: 1404
B4: עלות העבודות השירותים ומתן המכירות, העבודות | C4: -4585 | D4: -4865 | E4: -4983 | F4: -4344 | G4: -3553 | H4: -3454 | I4: -3702 | J4: -3746 | K4: -3703 | L4: -3602 | M4: -3915 | O4: -1278 | P4: -1207 | Q4: =C4-R4-S4-T4 -> -1066 | R4: -1157 | S4: -1184 | T4: -1178 | U4: =D4-V4-W4-X4 -> -1130 | V4: -1276 | W4: -1189 | X4: -1270 | Y4: =E4-Z4-AA4-AB4 -> -1158 | Z4: -1204 | AA4: -1341 | AB4: -1280 | AC4: =F4-AD4-AE4-AF4 -> -1181 | AD4: -1101 | AE4: -1047 | AF4: -1015 | AG4: =G4-AH4-AI4-AJ4 -> -912 | AH4: -839 | AI4: -883 | AJ4: -919 | AK4: =H4-AL4-AM4-AN4 -> -770 | AL4: -853 | AM4: -917 | AN4: -914 | AO4: =I4-AP4-AQ4-AR4 -> -903 | AP4: -913 | AQ4: -913 | AR4: -973
B5: רווח גולמי | C5: =C3+C4 -> 2256 | D5: =D3+D4 -> 2671 | E5: =E3+E4 -> 5032 | F5: =F3+F4 -> 2611 | G5: =G3+G4 -> 1490 | H5: =H3+H4 -> 1817 | I5: =I3+I4 -> 1854 | J5: =J3+J4 -> 1672 | ... M5: =M3+M4 -> 2196 | O5: =O3+O4 -> 554 | P5: =P3+P4 -> 560 | Q5: =Q3+Q4 -> 535 | R5: =R3+R4 -> 596 | S5: =S3+S4 -> 568 | T5: =T3+T4 -> 557 | U5: =U3+U4 -> 612 | V5: =V3+V4 -> 586 | ... AR5: =AR3+AR4 -> 431
B6: הוצאות מכירה ושיווק | C6: -1114 | D6: -1093 | E6: -1181 | F6: -1067 | G6: -766 | H6: -767 | I6: -798 | J6: -746 | K6: -722 | L6: -653 | M6: -839 | O6: -274 | P6: -268 | Q6: =C6-R6-S6-T6 -> -281 | R6: -280 | S6: -280 | T6: -273 | U6: =D6-V6-W6-X6 -> -286 | V6: -264 | W6: -279 | X6: -264 | Y6: =E6-Z6-AA6-AB6 -> -281 | Z6: -300 | AA6: -321 | AB6: -279 | AC6: =F6-AD6-AE6-AF6 -> -304 | AD6: -288 | AE6: -246 | AF6: -229 | AG6: =G6-AH6-AI6-AJ6 -> -204 | AH6: -191 | AI6: -183 | AJ6: -188 | AK6: =H6-AL6-AM6-AN6 -> -177 | AL6: -199 | AM6: -196 | AN6: -195 | AO6: =I6-AP6-AQ6-AR6 -> -210 | AP6: -191 | AQ6: -197 | AR6: -200
B7: הוצאות הנהלה וכלליות ואחרות | C7: -259 | D7: -260 | E7: -291 | F7: -276 | G7: -232 | H7: -254 | I7: -257 | J7: -261 | K7: -321 | L7: -350 | M7: -306 | O7: -72 | P7: -77 | Q7: =C7-R7-S7-T7 -> -68 | R7: -63 | S7: -64 | T7: -64 | U7: =D7-V7-W7-X7 -> -71 | V7: -66 | W7: -55 | X7: -68 | Y7: =E7-Z7-AA7-AB7 -> -78 | Z7: -70 | AA7: -74 | AB7: -69 | AC7: =F7-AD7-AE7-AF7 -> -78 | AD7: -69 | AE7: -67 | AF7: -62 | AG7: =G7-AH7-AI7-AJ7 -> -57 | AH7: -55 | AI7: -56 | AJ7: -64 | AK7: =H7-AL7-AM7-AN7 -> -64 | AL7: -62 | AM7: -65 | AN7: -63 | AO7: =I7-AP7-AQ7-AR7 -> -62 | AP7: -63 | AQ7: -62 | AR7: -70
B8: הוצאות מחקר ופיתוח | C8: -69 | D8: -71 | E8: -68 | F8: -64 | G8: -54 | H8: -50 | I8: -55 | J8: -55 | K8: -73 | L8: -74 | M8: -87 | O8: -19 | P8: -18 | Q8: =C8-R8-S8-T8 -> -19 | R8: -19 | S8: -14 | T8: -17 | U8: =D8-V8-W8-X8 -> -17 | V8: -17 | W8: -19 | X8: -18 | Y8: =E8-Z8-AA8-AB8 -> -15 | Z8: -18 | AA8: -17 | AB8: -18 | AC8: =F8-AD8-AE8-AF8 -> -19 | AD8: -16 | AE8: -14 | AF8: -15 | AG8: =G8-AH8-AI8-AJ8 -> -17 | AH8: -13 | AI8: -10 | AJ8: -14 | AK8: =H8-AL8-AM8-AN8 -> -12 | AL8: -13 | AM8: -12 | AN8: -13 | AO8: =I8-AP8-AQ8-AR8 -> -13 | AP8: -13 | AQ8: -15 | AR8: -14
B9: רווח תפעולי לפני הוצאות אחרות | C9: =SUM(C5:C8) -> 814 | D9: =SUM(D5:D8) -> 1247 | E9: =SUM(E5:E8) -> 3492 | F9: =SUM(F5:F8) -> 1204 | G9: =SUM(G5:G8) -> 438 | H9: =SUM(H5:H8) -> 746 | I9: =SUM(I5:I8) -> 744 | J9: =SUM(J5:J8) -> 610 | ... M9: =SUM(M5:M8) -> 964 | O9: =SUM(O5:O8) -> 189 | P9: =SUM(P5:P8) -> 197 | Q9: =SUM(Q5:Q8) -> 167 | R9: =SUM(R5:R8) -> 234 | S9: =SUM(S5:S8) -> 210 | T9: =SUM(T5:T8) -> 203 | U9: =SUM(U5:U8) -> 238 | V9: =SUM(V5:V8) -> 239 | ... AR9: =SUM(AR5:AR8) -> 147
B10: הכנסות (הוצאות) אחרות נטו | C10: =21-60 -> -39 | D10: =22-128 -> -106 | E10: =54-30 -> 24 | F10: =63-57 -> 6 | G10: =-256+20 -> -236 | H10: 10 | I10: =859-84 -> 775 | J10: =109-90 -> 19 | K10: =-618+71 -> -547 | L10: =250-211 -> 39 | M10: =-259+53 -> -206 | O10: =-11+3 -> -8 | P10: =-16+4 -> -12 | Q10: =C10-R10-S10-T10 -> -20 | R10: =-22+2 -> -20 | S10: =-2+3 -> 1 | T10: =3-3 -> 0 | U10: =D10-V10-W10-X10 -> -89 | V10: =2-14 -> -12 | W10: =10-2 -> 8 | X10: =3-16 -> -13 | Y10: =E10-Z10-AA10-AB10 -> -19 | Z10: 8 | AA10: =18-6 -> 12 | AB10: 23 | AC10: =F10-AD10-AE10-AF10 -> 5 | AD10: =14-9 -> 5 | AE10: =25-25 -> 0 | AF10: =-5+1 -> -4 | AG10: =G10-AH10-AI10-AJ10 -> 12 | AH10: -6 | AI10: =-244+4 -> -240 | AJ10: -2 | AK10: =H10-AL10-AM10-AN10 -> 5 | AL10: =5-2 -> 3 | AM10: =10-5 -> 5 | AN10: =13-16 -> -3 | AO10: =I10-AP10-AQ10-AR10 -> -56 | AP10: =19-14 -> 5 | AQ10: =-16+4 -> -12 | AR10: =846-8 -> 838
B11: הוצאות מימון | C11: -181 | D11: -259 | E11: -327 | F11: -216 | G11: -219 | H11: -220 | I11: -214 | J11: -229 | K11: -157 | L11: -160 | M11: -279 | O11: -98 | P11: -62 | Q11: =C11-R11-S11-T11 -> -16 | R11: -46 | S11: -59 | T11: -60 | U11: =D11-V11-W11-X11 -> -4 | V11: -79 | W11: =-89 -> -89 | X11: -87 | Y11: =E11-Z11-AA11-AB11 -> -65 | Z11: -57 | AA11: -138 | AB11: -67 | AC11: =F11-AD11-AE11-AF11 -> -38 | AD11: -54 | AE11: -64 | AF11: -60 | AG11: =G11-AH11-AI11-AJ11 -> -40 | AH11: -52 | AI11: -54 | AJ11: -73 | AK11: =H11-AL11-AM11-AN11 -> -25 | AL11: -67 | AM11: -49 | AN11: -79 | AO11: =I11-AP11-AQ11-AR11 -> -56 | AP11: -42 | AQ11: -76 | AR11: -40
B12: הכנסות מימון | C12: 41 | D12: 91 | E12: 214 | F12: 94 | G12: 61 | H12: 91 | I12: 56 | J12: 105 | K12: 25 | L12: 52 | M12: 122 | O12: 85 | P12: 25 | Q12: =C12-R12-S12-T12 -> -17 | R12: 7 | S12: 26 | T12: 25 | U12: =D12-V12-W12-X12 -> -29 | V12: 37 | W12: 40 | X12: 43 | Y12: =E12-Z12-AA12-AB12 -> 24 | Z12: 33 | AA12: 124 | AB12: 33 | AC12: =F12-AD12-AE12-AF12 -> 0 | AD12: 20 | AE12: 34 | AF12: 40 | AG12: =G12-AH12-AI12-AJ12 -> -6 | AH12: 23 | AI12: 23 | AJ12: 21 | AK12: =H12-AL12-AM12-AN12 -> 0 | AL12: 35 | AM12: 12 | AN12: 44 | AO12: =I12-AP12-AQ12-AR12 -> -10 | AP12: 19 | AQ12: 22 | AR12: 25
B13: הוצאות הכנסות מימון, נטו | C13: =SUM(C11:C12) -> -140 | D13: =SUM(D11:D12) -> -168 | E13: =SUM(E11:E12) -> -113 | F13: =SUM(F11:F12) -> -122 | G13: =SUM(G11:G12) -> -158 | H13: =SUM(H11:H12) -> -129 | I13: =SUM(I11:I12) -> -158 | J13: =SUM(J11:J12) -> -124 | ... M13: =SUM(M11:M12) -> -157 | O13: =SUM(O11:O12) -> -13 | P13: =SUM(P11:P12) -> -37 | Q13: =SUM(Q11:Q12) -> -33 | R13: =SUM(R11:R12) -> -39 | S13: =SUM(S11:S12) -> -33 | T13: =SUM(T11:T12) -> -35 | U13: =SUM(U11:U12) -> -33 | V13: =SUM(V11:V12) -> -42 | ... AR13: =SUM(AR11:AR12) -> -15
B14: חלק ברווחי כלולות | C14: 1 | D14: 1 | E14: 1 | F14: 4 | G14: 5 | H14: 1 | I14: 3 | J14: 0 | K14: 18 | L14: 11 | M14: 31 | O14: 0 | P14: 0 | Q14: =C14-R14-S14-T14 -> 0 | R14: 1 | S14: 0 | T14: 0 | U14: =D14-V14-W14-X14 -> 1 | V14: 0 | W14: 0 | X14: 0 | Y14: =E14-Z14-AA14-AB14 -> 1 | Z14: 0 | AA14: 0 | AB14: 0 | AC14: =F14-AD14-AE14-AF14 -> 3 | AD14: 0 | AE14: 1 | AF14: 0 | AG14: =G14-AH14-AI14-AJ14 -> 1 | AH14: 2 | AI14: 1 | AJ14: 1 | AL14: 0 | AM14: 1 | AN14: 0 | AP14: -1 | AQ14: 0 | AR14: 1
B15: רווח לפני מיסים | C15: =C9+C10+C13+C14 -> 636 | D15: =D9+D10+D13+D14 -> 974 | E15: =E9+E10+E13+E14 -> 3404 | F15: =F9+F10+F13+F14 -> 1092 | G15: =G9+G10+G13+G14 -> 49 | H15: =H9+H10+H13+H14 -> 628 | I15: =I9+I10+I13+I14 -> 1364 | J15: =J9+J10+J13+J14 -> 505 | ... M15: =M9+M10+M13+M14 -> 632 | O15: =O9+O10+O13+O14 -> 168 | P15: =P9+P10+P13+P14 -> 148 | Q15: =Q9+Q10+Q13+Q14 -> 114 | R15: =R9+R10+R13+R14 -> 176 | S15: =S9+S10+S13+S14 -> 178 | T15: =T9+T10+T13+T14 -> 168 | U15: =U9+U10+U13+U14 -> 117 | V15: =V9+V10+V13+V14 -> 185 | ... AR15: =AR9+AR10+AR13+AR14 -> 971
B16: מיסים על הכנסה | C16: -172 | D16: -287 | E16: -1185 | F16: -260 | G16: -25 | H16: -147 | I16: -129 | J16: -158 | K16: -55 | L16: -162 | M16: -166 | O16: -60 | P16: -42 | Q16: =C16-R16-S16-T16 -> -33 | R16: -49 | S16: -48 | T16: -42 | U16: =D16-V16-W16-X16 -> -33 | V16: -43 | W16: -84 | X16: -127 | Y16: =E16-Z16-AA16-AB16 -> -158 | Z16: -276 | AA16: -540 | AB16: -211 | AC16: =F16-AD16-AE16-AF16 -> -128 | AD16: -45 | AE16: -64 | AF16: -23 | AG16: =G16-AH16-AI16-AJ16 -> -24 | AH16: -14 | AI16: 33 | AJ16: -20 | AK16: =H16-AL16-AM16-AN16 -> -15 | AL16: -35 | AM16: -46 | AN16: -51 | AO16: =I16-AP16-AQ16-AR16 -> -19 | AP16: -45 | AQ16: -20 | AR16: -45
B17: רווח נקי | C17: =SUM(C15:C16) -> 464 | D17: =SUM(D15:D16) -> 687 | E17: =SUM(E15:E16) -> 2219 | F17: =SUM(F15:F16) -> 832 | G17: =SUM(G15:G16) -> 24 | H17: =SUM(H15:H16) -> 481 | I17: =SUM(I15:I16) -> 1235 | J17: =SUM(J15:J16) -> 347 | ... M17: =SUM(M15:M16) -> 466 | O17: =SUM(O15:O16) -> 108 | P17: =SUM(P15:P16) -> 106 | Q17: =SUM(Q15:Q16) -> 81 | R17: =SUM(R15:R16) -> 127 | S17: =SUM(S15:S16) -> 130 | T17: =SUM(T15:T16) -> 126 | U17: =SUM(U15:U16) -> 84 | V17: =SUM(V15:V16) -> 142 | ... AR17: =SUM(AR15:AR16) -> 926
B19: רווח נקי המיוחס לבעלי המניות | C19: =C17-C20 -> 407 | D19: =D17-D20 -> 647 | E19: =E17-E20 -> 2159 | F19: =F17-F20 -> 783 | G19: =G17-G20 -> 11 | H19: =H17-H20 -> 475 | I19: =I17-I20 -> 1240 | J19: =J17-J20 -> 364 | ... M19: =M17-M20 -> 464 | O19: =O17-O20 -> 93 | P19: =P17-P20 -> 91 | Q19: =C19-R19-S19-T19 -> 70 | R19: =R17-R20 -> 113 | S19: =S17-S20 -> 115 | T19: =T17-T20 -> 109 | U19: =#REF!-V19-W19-X19 -> #REF! | V19: =V17-V20 -> 137 | W19: =W17-W20 -> 163 | X19: =X17-X20 -> 269 | Y19: =E19-Z19-AA19-AB19 -> 331 | Z19: =Z17-Z20 -> 633 | AA19: =AA17-AA20 -> 563 | AB19: =AB17-AB20 -> 632 | AC19: =F19-AD19-AE19-AF19 -> 283 | AD19: =AD17-AD20 -> 225 | AE19: =AE17-AE20 -> 140 | AF19: =AF17-AF20 -> 135 | AG19: =G19-AH19-AI19-AJ19 -> 65 | AH19: =AH17-AH20 -> 54 | AI19: =AI17-AI20 -> -168 | AJ19: =AJ17-AJ20 -> 60 | AK19: =AK17-AK20 -> 48 | AL19: =AL17-AL20 -> 130 | AM19: =AM17-AM20 -> 158 | AN19: =AN17-AN20 -> 139 | AO19: =AO17-AO20 -> 79 | ... AR19: =AR17-AR20 -> 928
B20: רווח נקי המיוחס לזכויות שאינם מקנות שליטה | C20: 57 | D20: 40 | E20: 60 | F20: 49 | G20: 13 | H20: 6 | I20: -5 | J20: -17 | K20: -50 | L20: -3 | M20: 2 | O20: 15 | P20: 15 | Q20: =C20-R20-S20-T20 -> 11 | R20: 14 | S20: 15 | T20: 17 | U20: =#REF!-V20-W20-X20 -> #REF! | V20: 5 | W20: 4 | X20: 25 | Y20: =E20-Z20-AA20-AB20 -> 11 | Z20: 2 | AA20: 22 | AB20: 25 | AC20: =F20-AD20-AE20-AF20 -> 15 | AD20: 17 | AE20: 10 | AF20: 7 | AG20: =G20-AH20-AI20-AJ20 -> 5 | AH20: 5 | AI20: 2 | AJ20: 1 | AK20: =H20-AL20-AM20-AN20 -> 0 | AL20: 4 | AM20: 0 | AN20: 2 | AO20: =I20-AP20-AQ20-AR20 -> 2 | AP20: -2 | AQ20: -3 | AR20: -2
B22: צמיחה בהכנסות | C22: =C3/D3-1 -> -0.092223992 | D22: =D3/E3-1 -> -0.24752871 | E22: =E3/F3-1 -> 0.43997124 | F22: =F3/G3-1 -> 0.3791394 | G22: =G3/H3-1 -> -0.043255549 | H22: =H3/I3-1 -> -0.051295896 | I22: =I3/J3-1 -> 0.025470653 | J22: =J3/K3-1 -> 0.010255454 | ... L22: =L3/M3-1 -> -0.11552937 | O22: =O3/P3-1 -> 0.036785512 | P22: =P3/Q3-1 -> 0.1036852 | Q22: =Q3/R3-1 -> -0.0867085 | R22: =R3/S3-1 -> 0.00057077626 | S22: =S3/T3-1 -> 0.0097982709 | T22: =T3/U3-1 -> -0.0040183697 | U22: =U3/V3-1 -> -0.064446831 | V22: =V3/W3-1 -> 0.015267176 | ... AQ22: =AQ3/AR3-1 -> -0.023504274
B24: שיעור מסך הכנסות
B25: =B4 -> עלות העבודות השירותים ומתן המכירות, העבודות | C25: =IFERROR(IF(-C4/C$3<0,C4/C$3,-C4/C$3),"") -> 0.67022365 | D25: =IFERROR(IF(-D4/D$3<0,D4/D$3,-D4/D$3),"") -> 0.64556794 | E25: =IFERROR(IF(-E4/E$3<0,E4/E$3,-E4/E$3),"") -> 0.49755367 | F25: =IFERROR(IF(-F4/F$3<0,F4/F$3,-F4/F$3),"") -> 0.62458663 | G25: =IFERROR(IF(-G4/G$3<0,G4/G$3,-G4/G$3),"") -> 0.70454095 | H25: =IFERROR(IF(-H4/H$3<0,H4/H$3,-H4/H$3),"") -> 0.65528363 | I25: =IFERROR(IF(-I4/I$3<0,I4/I$3,-I4/I$3),"") -> 0.6663067 | J25: =IFERROR(IF(-J4/J$3<0,J4/J$3,-J4/J$3),"") -> 0.69139904 | ... M25: =IFERROR(IF(-M4/M$3<0,M4/M$3,-M4/M$3),"") -> 0.64064801 | O25: =IFERROR(IF(-O4/O$3<0,O4/O$3,-O4/O$3),"") -> 0.69759825 | P25: =IFERROR(IF(-P4/P$3<0,P4/P$3,-P4/P$3),"") -> 0.68307866 | Q25: =IFERROR(IF(-Q4/Q$3<0,Q4/Q$3,-Q4/Q$3),"") -> 0.66583385 | R25: =IFERROR(IF(-R4/R$3<0,R4/R$3,-R4/R$3),"") -> 0.66001141 | S25: =IFERROR(IF(-S4/S$3<0,S4/S$3,-S4/S$3),"") -> 0.67579909 | T25: =IFERROR(IF(-T4/T$3<0,T4/T$3,-T4/T$3),"") -> 0.67896254 | U25: =IFERROR(IF(-U4/U$3<0,U4/U$3,-U4/U$3),"") -> 0.64867968 | V25: =IFERROR(IF(-V4/V$3<0,V4/V$3,-V4/V$3),"") -> 0.68528464 | ... AR25: =IFERROR(IF(-AR4/AR$3<0,AR4/AR$3,-AR4/AR$3),"") -> 0.69301994
B26: =B5 -> רווח גולמי | C26: =IFERROR(IF(-C5/C$3<0,C5/C$3,-C5/C$3),"") -> 0.32977635 | D26: =IFERROR(IF(-D5/D$3<0,D5/D$3,-D5/D$3),"") -> 0.35443206 | E26: =IFERROR(IF(-E5/E$3<0,E5/E$3,-E5/E$3),"") -> 0.50244633 | F26: =IFERROR(IF(-F5/F$3<0,F5/F$3,-F5/F$3),"") -> 0.37541337 | G26: =IFERROR(IF(-G5/G$3<0,G5/G$3,-G5/G$3),"") -> 0.29545905 | H26: =IFERROR(IF(-H5/H$3<0,H5/H$3,-H5/H$3),"") -> 0.34471637 | I26: =IFERROR(IF(-I5/I$3<0,I5/I$3,-I5/I$3),"") -> 0.3336933 | J26: =IFERROR(IF(-J5/J$3<0,J5/J$3,-J5/J$3),"") -> 0.30860096 | ... M26: =IFERROR(IF(-M5/M$3<0,M5/M$3,-M5/M$3),"") -> 0.35935199 | O26: =IFERROR(IF(-O5/O$3<0,O5/O$3,-O5/O$3),"") -> 0.30240175 | P26: =IFERROR(IF(-P5/P$3<0,P5/P$3,-P5/P$3),"") -> 0.31692134 | Q26: =IFERROR(IF(-Q5/Q$3<0,Q5/Q$3,-Q5/Q$3),"") -> 0.33416615 | R26: =IFERROR(IF(-R5/R$3<0,R5/R$3,-R5/R$3),"") -> 0.33998859 | S26: =IFERROR(IF(-S5/S$3<0,S5/S$3,-S5/S$3),"") -> 0.32420091 | T26: =IFERROR(IF(-T5/T$3<0,T5/T$3,-T5/T$3),"") -> 0.32103746 | U26: =IFERROR(IF(-U5/U$3<0,U5/U$3,-U5/U$3),"") -> 0.35132032 | V26: =IFERROR(IF(-V5/V$3<0,V5/V$3,-V5/V$3),"") -> 0.31471536 | ... AR26: =IFERROR(IF(-AR5/AR$3<0,AR5/AR$3,-AR5/AR$3),"") -> 0.30698006
B27: =B6 -> הוצאות מכירה ושיווק | C27: =IFERROR(IF(-C6/C$3<0,C6/C$3,-C6/C$3),"") -> 0.16284169 | D27: =IFERROR(IF(-D6/D$3<0,D6/D$3,-D6/D$3),"") -> 0.14503715 | E27: =IFERROR(IF(-E6/E$3<0,E6/E$3,-E6/E$3),"") -> 0.11792312 | F27: =IFERROR(IF(-F6/F$3<0,F6/F$3,-F6/F$3),"") -> 0.15341481 | G27: =IFERROR(IF(-G6/G$3<0,G6/G$3,-G6/G$3),"") -> 0.15189371 | H27: =IFERROR(IF(-H6/H$3<0,H6/H$3,-H6/H$3),"") -> 0.14551319 | I27: =IFERROR(IF(-I6/I$3<0,I6/I$3,-I6/I$3),"") -> 0.14362851 | J27: =IFERROR(IF(-J6/J$3<0,J6/J$3,-J6/J$3),"") -> 0.13768918 | ... M27: =IFERROR(IF(-M6/M$3<0,M6/M$3,-M6/M$3),"") -> 0.13729341 | O27: =IFERROR(IF(-O6/O$3<0,O6/O$3,-O6/O$3),"") -> 0.14956332 | P27: =IFERROR(IF(-P6/P$3<0,P6/P$3,-P6/P$3),"") -> 0.1516695 | Q27: =IFERROR(IF(-Q6/Q$3<0,Q6/Q$3,-Q6/Q$3),"") -> 0.1755153 | R27: =IFERROR(IF(-R6/R$3<0,R6/R$3,-R6/R$3),"") -> 0.15972618 | S27: =IFERROR(IF(-S6/S$3<0,S6/S$3,-S6/S$3),"") -> 0.15981735 | T27: =IFERROR(IF(-T6/T$3<0,T6/T$3,-T6/T$3),"") -> 0.1573487 | U27: =IFERROR(IF(-U6/U$3<0,U6/U$3,-U6/U$3),"") -> 0.1641791 | V27: =IFERROR(IF(-V6/V$3<0,V6/V$3,-V6/V$3),"") -> 0.14178303 | ... AR27: =IFERROR(IF(-AR6/AR$3<0,AR6/AR$3,-AR6/AR$3),"") -> 0.14245014
B28: =B7 -> הוצאות הנהלה וכלליות ואחרות | C28: =IFERROR(IF(-C7/C$3<0,C7/C$3,-C7/C$3),"") -> 0.037859962 | D28: =IFERROR(IF(-D7/D$3<0,D7/D$3,-D7/D$3),"") -> 0.034501062 | E28: =IFERROR(IF(-E7/E$3<0,E7/E$3,-E7/E$3),"") -> 0.029056415 | F28: =IFERROR(IF(-F7/F$3<0,F7/F$3,-F7/F$3),"") -> 0.039683681 | G28: =IFERROR(IF(-G7/G$3<0,G7/G$3,-G7/G$3),"") -> 0.046004362 | H28: =IFERROR(IF(-H7/H$3<0,H7/H$3,-H7/H$3),"") -> 0.0481882 | I28: =IFERROR(IF(-I7/I$3<0,I7/I$3,-I7/I$3),"") -> 0.046256299 | J28: =IFERROR(IF(-J7/J$3<0,J7/J$3,-J7/J$3),"") -> 0.048172757 | ... M28: =IFERROR(IF(-M7/M$3<0,M7/M$3,-M7/M$3),"") -> 0.050073638 | O28: =IFERROR(IF(-O7/O$3<0,O7/O$3,-O7/O$3),"") -> 0.03930131 | P28: =IFERROR(IF(-P7/P$3<0,P7/P$3,-P7/P$3),"") -> 0.043576684 | Q28: =IFERROR(IF(-Q7/Q$3<0,Q7/Q$3,-Q7/Q$3),"") -> 0.042473454 | R28: =IFERROR(IF(-R7/R$3<0,R7/R$3,-R7/R$3),"") -> 0.035938391 | S28: =IFERROR(IF(-S7/S$3<0,S7/S$3,-S7/S$3),"") -> 0.03652968 | T28: =IFERROR(IF(-T7/T$3<0,T7/T$3,-T7/T$3),"") -> 0.036887608 | U28: =IFERROR(IF(-U7/U$3<0,U7/U$3,-U7/U$3),"") -> 0.04075775 | V28: =IFERROR(IF(-V7/V$3<0,V7/V$3,-V7/V$3),"") -> 0.035445757 | ... AR28: =IFERROR(IF(-AR7/AR$3<0,AR7/AR$3,-AR7/AR$3),"") -> 0.04985755
B29: =B8 -> הוצאות מחקר ופיתוח | C29: =IFERROR(IF(-C8/C$3<0,C8/C$3,-C8/C$3),"") -> 0.010086245 | D29: =IFERROR(IF(-D8/D$3<0,D8/D$3,-D8/D$3),"") -> 0.0094214437 | E29: =IFERROR(IF(-E8/E$3<0,E8/E$3,-E8/E$3),"") -> 0.0067898153 | F29: =IFERROR(IF(-F8/F$3<0,F8/F$3,-F8/F$3),"") -> 0.0092020129 | G29: =IFERROR(IF(-G8/G$3<0,G8/G$3,-G8/G$3),"") -> 0.010707912 | H29: =IFERROR(IF(-H8/H$3<0,H8/H$3,-H8/H$3),"") -> 0.0094858661 | I29: =IFERROR(IF(-I8/I$3<0,I8/I$3,-I8/I$3),"") -> 0.0098992081 | J29: =IFERROR(IF(-J8/J$3<0,J8/J$3,-J8/J$3),"") -> 0.010151347 | ... M29: =IFERROR(IF(-M8/M$3<0,M8/M$3,-M8/M$3),"") -> 0.014236622 | O29: =IFERROR(IF(-O8/O$3<0,O8/O$3,-O8/O$3),"") -> 0.010371179 | P29: =IFERROR(IF(-P8/P$3<0,P8/P$3,-P8/P$3),"") -> 0.010186757 | Q29: =IFERROR(IF(-Q8/Q$3<0,Q8/Q$3,-Q8/Q$3),"") -> 0.011867583 | R29: =IFERROR(IF(-R8/R$3<0,R8/R$3,-R8/R$3),"") -> 0.010838562 | S29: =IFERROR(IF(-S8/S$3<0,S8/S$3,-S8/S$3),"") -> 0.0079908676 | T29: =IFERROR(IF(-T8/T$3<0,T8/T$3,-T8/T$3),"") -> 0.0097982709 | U29: =IFERROR(IF(-U8/U$3<0,U8/U$3,-U8/U$3),"") -> 0.0097588978 | V29: =IFERROR(IF(-V8/V$3<0,V8/V$3,-V8/V$3),"") -> 0.0091299678 | ... AR29: =IFERROR(IF(-AR8/AR$3<0,AR8/AR$3,-AR8/AR$3),"") -> 0.00997151
B30: =B10 -> הכנסות (הוצאות) אחרות נטו | C30: =IFERROR(IF(-C10/C$3<0,C10/C$3,-C10/C$3),"") -> 0.0057009209 | D30: =IFERROR(IF(-D10/D$3<0,D10/D$3,-D10/D$3),"") -> 0.014065817 | E30: =IFERROR(IF(-E10/E$3<0,E10/E$3,-E10/E$3),"") -> 0.0023964054 | F30: =IFERROR(IF(-F10/F$3<0,F10/F$3,-F10/F$3),"") -> 0.00086268871 | G30: =IFERROR(IF(-G10/G$3<0,G10/G$3,-G10/G$3),"") -> 0.046797541 | H30: =IFERROR(IF(-H10/H$3<0,H10/H$3,-H10/H$3),"") -> 0.0018971732 | I30: =IFERROR(IF(-I10/I$3<0,I10/I$3,-I10/I$3),"") -> 0.13948884 | J30: =IFERROR(IF(-J10/J$3<0,J10/J$3,-J10/J$3),"") -> 0.0035068291 | ... M30: =IFERROR(IF(-M10/M$3<0,M10/M$3,-M10/M$3),"") -> 0.033709704 | O30: =IFERROR(IF(-O10/O$3<0,O10/O$3,-O10/O$3),"") -> 0.0043668122 | P30: =IFERROR(IF(-P10/P$3<0,P10/P$3,-P10/P$3),"") -> 0.0067911715 | Q30: =IFERROR(IF(-Q10/Q$3<0,Q10/Q$3,-Q10/Q$3),"") -> 0.012492192 | R30: =IFERROR(IF(-R10/R$3<0,R10/R$3,-R10/R$3),"") -> 0.011409013 | S30: =IFERROR(IF(-S10/S$3<0,S10/S$3,-S10/S$3),"") -> 0.00057077626 | T30: =IFERROR(IF(-T10/T$3<0,T10/T$3,-T10/T$3),"") -> 0 | U30: =IFERROR(IF(-U10/U$3<0,U10/U$3,-U10/U$3),"") -> 0.0510907 | V30: =IFERROR(IF(-V10/V$3<0,V10/V$3,-V10/V$3),"") -> 0.0064446831 | ... AR30: =IFERROR(IF(-AR10/AR$3<0,AR10/AR$3,-AR10/AR$3),"") -> 0.5968661
C31: =IFERROR(IF(-#REF!/C$3<0,#REF!/C$3,-#REF!/C$3),"") | D31: =IFERROR(IF(-#REF!/D$3<0,#REF!/D$3,-#REF!/D$3),"") | E31: =IFERROR(IF(-#REF!/E$3<0,#REF!/E$3,-#REF!/E$3),"") | F31: =IFERROR(IF(-#REF!/F$3<0,#REF!/F$3,-#REF!/F$3),"") | G31: =IFERROR(IF(-#REF!/G$3<0,#REF!/G$3,-#REF!/G$3),"") | H31: =IFERROR(IF(-#REF!/H$3<0,#REF!/H$3,-#REF!/H$3),"") | I31: =IFERROR(IF(-#REF!/I$3<0,#REF!/I$3,-#REF!/I$3),"") | J31: =IFERROR(IF(-#REF!/J$3<0,#REF!/J$3,-#REF!/J$3),"") | ... M31: =IFERROR(IF(-#REF!/M$3<0,#REF!/M$3,-#REF!/M$3),"") | O31: =IFERROR(IF(-#REF!/O$3<0,#REF!/O$3,-#REF!/O$3),"") | P31: =IFERROR(IF(-#REF!/P$3<0,#REF!/P$3,-#REF!/P$3),"") | Q31: =IFERROR(IF(-#REF!/Q$3<0,#REF!/Q$3,-#REF!/Q$3),"") | R31: =IFERROR(IF(-#REF!/R$3<0,#REF!/R$3,-#REF!/R$3),"") | S31: =IFERROR(IF(-#REF!/S$3<0,#REF!/S$3,-#REF!/S$3),"") | T31: =IFERROR(IF(-#REF!/T$3<0,#REF!/T$3,-#REF!/T$3),"") | U31: =IFERROR(IF(-#REF!/U$3<0,#REF!/U$3,-#REF!/U$3),"") | V31: =IFERROR(IF(-#REF!/V$3<0,#REF!/V$3,-#REF!/V$3),"") | ... AR31: =IFERROR(IF(-#REF!/AR$3<0,#REF!/AR$3,-#REF!/AR$3),"")
B32: =B9 -> רווח תפעולי לפני הוצאות אחרות | C32: =IFERROR(IF(-C9/C$3<0,C9/C$3,-C9/C$3),"") -> 0.11898845 | D32: =IFERROR(IF(-D9/D$3<0,D9/D$3,-D9/D$3),"") -> 0.1654724 | E32: =IFERROR(IF(-E9/E$3<0,E9/E$3,-E9/E$3),"") -> 0.34867698 | F32: =IFERROR(IF(-F9/F$3<0,F9/F$3,-F9/F$3),"") -> 0.17311287 | G32: =IFERROR(IF(-G9/G$3<0,G9/G$3,-G9/G$3),"") -> 0.086853064 | H32: =IFERROR(IF(-H9/H$3<0,H9/H$3,-H9/H$3),"") -> 0.14152912 | I32: =IFERROR(IF(-I9/I$3<0,I9/I$3,-I9/I$3),"") -> 0.13390929 | J32: =IFERROR(IF(-J9/J$3<0,J9/J$3,-J9/J$3),"") -> 0.11258767 | ... M32: =IFERROR(IF(-M9/M$3<0,M9/M$3,-M9/M$3),"") -> 0.15774832 | O32: =IFERROR(IF(-O9/O$3<0,O9/O$3,-O9/O$3),"") -> 0.10316594 | P32: =IFERROR(IF(-P9/P$3<0,P9/P$3,-P9/P$3),"") -> 0.1114884 | Q32: =IFERROR(IF(-Q9/Q$3<0,Q9/Q$3,-Q9/Q$3),"") -> 0.10430981 | R32: =IFERROR(IF(-R9/R$3<0,R9/R$3,-R9/R$3),"") -> 0.13348545 | S32: =IFERROR(IF(-S9/S$3<0,S9/S$3,-S9/S$3),"") -> 0.11986301 | T32: =IFERROR(IF(-T9/T$3<0,T9/T$3,-T9/T$3),"") -> 0.11700288 | U32: =IFERROR(IF(-U9/U$3<0,U9/U$3,-U9/U$3),"") -> 0.13662457 | V32: =IFERROR(IF(-V9/V$3<0,V9/V$3,-V9/V$3),"") -> 0.12835661 | ... AR32: =IFERROR(IF(-AR9/AR$3<0,AR9/AR$3,-AR9/AR$3),"") -> 0.10470085
C33: =IFERROR(IF(-#REF!/C$3<0,#REF!/C$3,-#REF!/C$3),"") | D33: =IFERROR(IF(-#REF!/D$3<0,#REF!/D$3,-#REF!/D$3),"") | E33: =IFERROR(IF(-#REF!/E$3<0,#REF!/E$3,-#REF!/E$3),"") | F33: =IFERROR(IF(-#REF!/F$3<0,#REF!/F$3,-#REF!/F$3),"") | G33: =IFERROR(IF(-#REF!/G$3<0,#REF!/G$3,-#REF!/G$3),"") | H33: =IFERROR(IF(-#REF!/H$3<0,#REF!/H$3,-#REF!/H$3),"") | I33: =IFERROR(IF(-#REF!/I$3<0,#REF!/I$3,-#REF!/I$3),"") | J33: =IFERROR(IF(-#REF!/J$3<0,#REF!/J$3,-#REF!/J$3),"") | ... M33: =IFERROR(IF(-#REF!/M$3<0,#REF!/M$3,-#REF!/M$3),"") | O33: =IFERROR(IF(-#REF!/O$3<0,#REF!/O$3,-#REF!/O$3),"") | P33: =IFERROR(IF(-#REF!/P$3<0,#REF!/P$3,-#REF!/P$3),"") | Q33: =IFERROR(IF(-#REF!/Q$3<0,#REF!/Q$3,-#REF!/Q$3),"") | R33: =IFERROR(IF(-#REF!/R$3<0,#REF!/R$3,-#REF!/R$3),"") | S33: =IFERROR(IF(-#REF!/S$3<0,#REF!/S$3,-#REF!/S$3),"") | T33: =IFERROR(IF(-#REF!/T$3<0,#REF!/T$3,-#REF!/T$3),"") | U33: =IFERROR(IF(-#REF!/U$3<0,#REF!/U$3,-#REF!/U$3),"") | V33: =IFERROR(IF(-#REF!/V$3<0,#REF!/V$3,-#REF!/V$3),"") | ... AR33: =IFERROR(IF(-#REF!/AR$3<0,#REF!/AR$3,-#REF!/AR$3),"")
B34: =B11 -> הוצאות מימון | C34: =IFERROR(IF(-C11/C$3<0,C11/C$3,-C11/C$3),"") -> 0.02645812 | D34: =IFERROR(IF(-D11/D$3<0,D11/D$3,-D11/D$3),"") -> 0.034368365 | E34: =IFERROR(IF(-E11/E$3<0,E11/E$3,-E11/E$3),"") -> 0.032651023 | F34: =IFERROR(IF(-F11/F$3<0,F11/F$3,-F11/F$3),"") -> 0.031056794 | G34: =IFERROR(IF(-G11/G$3<0,G11/G$3,-G11/G$3),"") -> 0.043426532 | H34: =IFERROR(IF(-H11/H$3<0,H11/H$3,-H11/H$3),"") -> 0.041737811 | I34: =IFERROR(IF(-I11/I$3<0,I11/I$3,-I11/I$3),"") -> 0.038516919 | J34: =IFERROR(IF(-J11/J$3<0,J11/J$3,-J11/J$3),"") -> 0.042266519 | ... M34: =IFERROR(IF(-M11/M$3<0,M11/M$3,-M11/M$3),"") -> 0.045655376 | O34: =IFERROR(IF(-O11/O$3<0,O11/O$3,-O11/O$3),"") -> 0.05349345 | P34: =IFERROR(IF(-P11/P$3<0,P11/P$3,-P11/P$3),"") -> 0.035087719 | Q34: =IFERROR(IF(-Q11/Q$3<0,Q11/Q$3,-Q11/Q$3),"") -> 0.0099937539 | R34: =IFERROR(IF(-R11/R$3<0,R11/R$3,-R11/R$3),"") -> 0.02624073 | S34: =IFERROR(IF(-S11/S$3<0,S11/S$3,-S11/S$3),"") -> 0.033675799 | T34: =IFERROR(IF(-T11/T$3<0,T11/T$3,-T11/T$3),"") -> 0.034582133 | U34: =IFERROR(IF(-U11/U$3<0,U11/U$3,-U11/U$3),"") -> 0.0022962113 | V34: =IFERROR(IF(-V11/V$3<0,V11/V$3,-V11/V$3),"") -> 0.042427497 | ... AR34: =IFERROR(IF(-AR11/AR$3<0,AR11/AR$3,-AR11/AR$3),"") -> 0.028490028
B35: =B12 -> הכנסות מימון | C35: =IFERROR(IF(-C12/C$3<0,C12/C$3,-C12/C$3),"") -> 0.0059932758 | D35: =IFERROR(IF(-D12/D$3<0,D12/D$3,-D12/D$3),"") -> 0.012075372 | E35: =IFERROR(IF(-E12/E$3<0,E12/E$3,-E12/E$3),"") -> 0.021367948 | F35: =IFERROR(IF(-F12/F$3<0,F12/F$3,-F12/F$3),"") -> 0.013515457 | G35: =IFERROR(IF(-G12/G$3<0,G12/G$3,-G12/G$3),"") -> 0.012095975 | H35: =IFERROR(IF(-H12/H$3<0,H12/H$3,-H12/H$3),"") -> 0.017264276 | I35: =IFERROR(IF(-I12/I$3<0,I12/I$3,-I12/I$3),"") -> 0.010079194 | J35: =IFERROR(IF(-J12/J$3<0,J12/J$3,-J12/J$3),"") -> 0.019379845 | ... M35: =IFERROR(IF(-M12/M$3<0,M12/M$3,-M12/M$3),"") -> 0.019963999 | O35: =IFERROR(IF(-O12/O$3<0,O12/O$3,-O12/O$3),"") -> 0.04639738 | P35: =IFERROR(IF(-P12/P$3<0,P12/P$3,-P12/P$3),"") -> 0.014148274 | Q35: =IFERROR(IF(-Q12/Q$3<0,Q12/Q$3,-Q12/Q$3),"") -> 0.010618364 | R35: =IFERROR(IF(-R12/R$3<0,R12/R$3,-R12/R$3),"") -> 0.0039931546 | S35: =IFERROR(IF(-S12/S$3<0,S12/S$3,-S12/S$3),"") -> 0.014840183 | T35: =IFERROR(IF(-T12/T$3<0,T12/T$3,-T12/T$3),"") -> 0.014409222 | U35: =IFERROR(IF(-U12/U$3<0,U12/U$3,-U12/U$3),"") -> 0.016647532 | V35: =IFERROR(IF(-V12/V$3<0,V12/V$3,-V12/V$3),"") -> 0.019871106 | ... AR35: =IFERROR(IF(-AR12/AR$3<0,AR12/AR$3,-AR12/AR$3),"") -> 0.017806268
B36: =B13 -> הוצאות הכנסות מימון, נטו | C36: =IFERROR(IF(-C13/C$3<0,C13/C$3,-C13/C$3),"") -> 0.020464844 | D36: =IFERROR(IF(-D13/D$3<0,D13/D$3,-D13/D$3),"") -> 0.022292994 | E36: =IFERROR(IF(-E13/E$3<0,E13/E$3,-E13/E$3),"") -> 0.011283075 | F36: =IFERROR(IF(-F13/F$3<0,F13/F$3,-F13/F$3),"") -> 0.017541337 | G36: =IFERROR(IF(-G13/G$3<0,G13/G$3,-G13/G$3),"") -> 0.031330557 | H36: =IFERROR(IF(-H13/H$3<0,H13/H$3,-H13/H$3),"") -> 0.024473534 | I36: =IFERROR(IF(-I13/I$3<0,I13/I$3,-I13/I$3),"") -> 0.028437725 | J36: =IFERROR(IF(-J13/J$3<0,J13/J$3,-J13/J$3),"") -> 0.022886674 | ... M36: =IFERROR(IF(-M13/M$3<0,M13/M$3,-M13/M$3),"") -> 0.025691376 | O36: =IFERROR(IF(-O13/O$3<0,O13/O$3,-O13/O$3),"") -> 0.0070960699 | P36: =IFERROR(IF(-P13/P$3<0,P13/P$3,-P13/P$3),"") -> 0.020939445 | Q36: =IFERROR(IF(-Q13/Q$3<0,Q13/Q$3,-Q13/Q$3),"") -> 0.020612117 | R36: =IFERROR(IF(-R13/R$3<0,R13/R$3,-R13/R$3),"") -> 0.022247576 | S36: =IFERROR(IF(-S13/S$3<0,S13/S$3,-S13/S$3),"") -> 0.018835616 | T36: =IFERROR(IF(-T13/T$3<0,T13/T$3,-T13/T$3),"") -> 0.020172911 | U36: =IFERROR(IF(-U13/U$3<0,U13/U$3,-U13/U$3),"") -> 0.018943743 | V36: =IFERROR(IF(-V13/V$3<0,V13/V$3,-V13/V$3),"") -> 0.022556391 | ... AR36: =IFERROR(IF(-AR13/AR$3<0,AR13/AR$3,-AR13/AR$3),"") -> 0.010683761
B37: =B15 -> רווח לפני מיסים | C37: =IFERROR(IF(-C15/C$3<0,C15/C$3,-C15/C$3),"") -> 0.092968864 | D37: =IFERROR(IF(-D15/D$3<0,D15/D$3,-D15/D$3),"") -> 0.12924628 | E37: =IFERROR(IF(-E15/E$3<0,E15/E$3,-E15/E$3),"") -> 0.33989016 | F37: =IFERROR(IF(-F15/F$3<0,F15/F$3,-F15/F$3),"") -> 0.15700935 | G37: =IFERROR(IF(-G15/G$3<0,G15/G$3,-G15/G$3),"") -> 0.0097164386 | H37: =IFERROR(IF(-H15/H$3<0,H15/H$3,-H15/H$3),"") -> 0.11914248 | I37: =IFERROR(IF(-I15/I$3<0,I15/I$3,-I15/I$3),"") -> 0.24550036 | J37: =IFERROR(IF(-J15/J$3<0,J15/J$3,-J15/J$3),"") -> 0.093207826 | ... M37: =IFERROR(IF(-M15/M$3<0,M15/M$3,-M15/M$3),"") -> 0.10342006 | O37: =IFERROR(IF(-O15/O$3<0,O15/O$3,-O15/O$3),"") -> 0.091703057 | P37: =IFERROR(IF(-P15/P$3<0,P15/P$3,-P15/P$3),"") -> 0.083757782 | Q37: =IFERROR(IF(-Q15/Q$3<0,Q15/Q$3,-Q15/Q$3),"") -> 0.071205497 | R37: =IFERROR(IF(-R15/R$3<0,R15/R$3,-R15/R$3),"") -> 0.10039932 | S37: =IFERROR(IF(-S15/S$3<0,S15/S$3,-S15/S$3),"") -> 0.10159817 | T37: =IFERROR(IF(-T15/T$3<0,T15/T$3,-T15/T$3),"") -> 0.096829971 | U37: =IFERROR(IF(-U15/U$3<0,U15/U$3,-U15/U$3),"") -> 0.067164179 | V37: =IFERROR(IF(-V15/V$3<0,V15/V$3,-V15/V$3),"") -> 0.099355532 | ... AR37: =IFERROR(IF(-AR15/AR$3<0,AR15/AR$3,-AR15/AR$3),"") -> 0.69159544
B38: =B16 -> מיסים על הכנסה | C38: =IFERROR(IF(-C16/C$3<0,C16/C$3,-C16/C$3),"") -> 0.025142523 | D38: =IFERROR(IF(-D16/D$3<0,D16/D$3,-D16/D$3),"") -> 0.038083864 | E38: =IFERROR(IF(-E16/E$3<0,E16/E$3,-E16/E$3),"") -> 0.11832252 | F38: =IFERROR(IF(-F16/F$3<0,F16/F$3,-F16/F$3),"") -> 0.037383178 | G38: =IFERROR(IF(-G16/G$3<0,G16/G$3,-G16/G$3),"") -> 0.0049573666 | H38: =IFERROR(IF(-H16/H$3<0,H16/H$3,-H16/H$3),"") -> 0.027888446 | I38: =IFERROR(IF(-I16/I$3<0,I16/I$3,-I16/I$3),"") -> 0.023218143 | J38: =IFERROR(IF(-J16/J$3<0,J16/J$3,-J16/J$3),"") -> 0.029162052 | ... M38: =IFERROR(IF(-M16/M$3<0,M16/M$3,-M16/M$3),"") -> 0.02716413 | O38: =IFERROR(IF(-O16/O$3<0,O16/O$3,-O16/O$3),"") -> 0.032751092 | P38: =IFERROR(IF(-P16/P$3<0,P16/P$3,-P16/P$3),"") -> 0.0237691 | Q38: =IFERROR(IF(-Q16/Q$3<0,Q16/Q$3,-Q16/Q$3),"") -> 0.020612117 | R38: =IFERROR(IF(-R16/R$3<0,R16/R$3,-R16/R$3),"") -> 0.027952082 | S38: =IFERROR(IF(-S16/S$3<0,S16/S$3,-S16/S$3),"") -> 0.02739726 | T38: =IFERROR(IF(-T16/T$3<0,T16/T$3,-T16/T$3),"") -> 0.024207493 | U38: =IFERROR(IF(-U16/U$3<0,U16/U$3,-U16/U$3),"") -> 0.018943743 | V38: =IFERROR(IF(-V16/V$3<0,V16/V$3,-V16/V$3),"") -> 0.023093448 | ... AR38: =IFERROR(IF(-AR16/AR$3<0,AR16/AR$3,-AR16/AR$3),"") -> 0.032051282
B39: =B17 -> רווח נקי | C39: =IFERROR(IF(-C17/C$3<0,C17/C$3,-C17/C$3),"") -> 0.067826341 | D39: =IFERROR(IF(-D17/D$3<0,D17/D$3,-D17/D$3),"") -> 0.09116242 | E39: =IFERROR(IF(-E17/E$3<0,E17/E$3,-E17/E$3),"") -> 0.22156765 | F39: =IFERROR(IF(-F17/F$3<0,F17/F$3,-F17/F$3),"") -> 0.11962617 | G39: =IFERROR(IF(-G17/G$3<0,G17/G$3,-G17/G$3),"") -> 0.004759072 | H39: =IFERROR(IF(-H17/H$3<0,H17/H$3,-H17/H$3),"") -> 0.091254031 | I39: =IFERROR(IF(-I17/I$3<0,I17/I$3,-I17/I$3),"") -> 0.22228222 | J39: =IFERROR(IF(-J17/J$3<0,J17/J$3,-J17/J$3),"") -> 0.064045773 | ... M39: =IFERROR(IF(-M17/M$3<0,M17/M$3,-M17/M$3),"") -> 0.076255932 | O39: =IFERROR(IF(-O17/O$3<0,O17/O$3,-O17/O$3),"") -> 0.058951965 | P39: =IFERROR(IF(-P17/P$3<0,P17/P$3,-P17/P$3),"") -> 0.059988681 | Q39: =IFERROR(IF(-Q17/Q$3<0,Q17/Q$3,-Q17/Q$3),"") -> 0.050593379 | R39: =IFERROR(IF(-R17/R$3<0,R17/R$3,-R17/R$3),"") -> 0.072447233 | S39: =IFERROR(IF(-S17/S$3<0,S17/S$3,-S17/S$3),"") -> 0.074200913 | T39: =IFERROR(IF(-T17/T$3<0,T17/T$3,-T17/T$3),"") -> 0.072622478 | U39: =IFERROR(IF(-U17/U$3<0,U17/U$3,-U17/U$3),"") -> 0.048220436 | V39: =IFERROR(IF(-V17/V$3<0,V17/V$3,-V17/V$3),"") -> 0.076262084 | ... AR39: =IFERROR(IF(-AR17/AR$3<0,AR17/AR$3,-AR17/AR$3),"") -> 0.65954416
A43: תזרים מזומנים | C43: =C$2 -> FY 2024 | D43: =D$2 -> FY 2023 | E43: =E$2 -> FY 2022 | F43: =F$2 -> FY 2021 | G43: =G$2 -> FY 2020 | H43: =H$2 -> FY 2019 | I43: =I$2 -> FY 2018 | J43: =J$2 -> FY 2017 | ... M43: =M$2 -> FY 2014 | O43: =O$2 -> Q2 2025 | P43: =P$2 -> Q1 2025 | Q43: =Q$2 -> Q4 2024 | R43: =R$2 -> Q3 2024 | S43: =S$2 -> Q2 2024 | T43: =T$2 -> Q1 2024 | U43: =U$2 -> Q4 2023 | V43: =V$2 -> Q3 2023 | ... AR43: =AR$2 -> Q1 2018
B45: רווח נקי | C45: =C17 -> 464 | D45: =D17 -> 687 | E45: =E17 -> 2219 | F45: =F17 -> 832 | G45: =G17 -> 24 | H45: =H17 -> 481 | I45: =I17 -> 1235 | J45: =J17 -> 347 | ... M45: =M17 -> 466 | O45: =O17 -> 108 | P45: =P17 -> 106 | Q45: =Q17 -> 81 | R45: =R17 -> 127 | S45: =S17 -> 130 | T45: =T17 -> 126 | U45: =U17 -> 84 | V45: =V17 -> 142 | ... AR45: =AR17 -> 926
B46: פחת והפחתות | C46: 596 | D46: 536 | E46: 498 | F46: 490 | G46: 489 | H46: 443 | I46: 403 | J46: 390 | K46: 401 | L46: 430 | M46: 427 | O46: 150 | P46: 151 | Q46: =C46-R46-S46-T46 -> 157 | R46: 140 | S46: 152 | T46: 147 | U46: =D46-V46-W46-X46 -> 146 | V46: 119 | W46: 141 | X46: 130 | Y46: =E46-Z46-AA46-AB46 -> 136 | Z46: 121 | AA46: 119 | AB46: 122 | AC46: =F46-AD46-AE46-AF46 -> 126 | AD46: 123 | AE46: 124 | AF46: 117 | AG46: =G46-AH46-AI46-AJ46 -> 170 | AH46: 82 | AI46: 119 | AJ46: 118 | AK46: =H46-AL46-AM46-AN46 -> 113 | AL46: 110 | AM46: 109 | AN46: 111 | AP46: 94 | AQ46: 105 | AR46: 97
B47: (ביטול) הפסד מירידת ערך רכוש קבוע | C47: 14 | D47: 0 | E47: 0 | F47: -6 | G47: 90 | H47: -10 | I47: 17 | J47: 28 | K47: 5 | L47: -162 | M47: -23 | O47: 0 | P47: 0 | Q47: =C47-R47-S47-T47 -> 7 | R47: 7 | S47: 0 | T47: 0 | U47: =D47-V47-W47-X47 -> 0 | V47: 0 | W47: 0 | X47: 0 | Y47: =E47-Z47-AA47-AB47 -> 0 | Z47: 0 | AA47: 0 | AB47: 0 | AC47: =F47-AD47-AE47-AF47 -> 3 | AD47: 0 | AE47: -9 | AF47: 0 | AG47: =G47-AH47-AI47-AJ47 -> -41 | AH47: 0 | AI47: 131 | AJ47: 0 | AK47: =H47-AL47-AM47-AN47 -> 0 | AL47: 0 | AM47: -10 | AN47: 0 | AP47: 3 | AQ47: 14 | AR47: 0
...

Sheet Reported Rev.. Split
C3: FY 2024 | D3: FY 2023 | E3: FY 2022 | F3: FY 2021 | G3: FY 2020 | H3: FY 2019 | I3: FY 2018 | J3: FY 2017 | K3: FY 2016 | M3: Q22025 | N3: Q12025 | O3: Q42024 | P3: Q32024 | Q3: Q22024 | R3: Q12024 | S3: Q42023 | T3: Q32023 | U3: Q22023 | V3: Q12023 | W3: Q12022 | X3: Q42021 | Y3: Q32021 | Z3: Q22021 | AA3: Q12021 | AB3: Q42020 | AC3: Q32020 | AD3: Q2 2020 | AE3: Q1 2020 | AF3: Q4 2019 | AG3: Q3 2019 | AH3: Q2 2019 | AI3: Q1 2019 | AJ3: Q4 2018 | AK3: Q3 2018 | AL3: Q2 2018 | AM3: Q1 2018
B5: הכנסות מחצוניים לפי מגזרים
B6: אשלג | C6: =O6+P6+Q6+R6 -> 1462 | D6: 1973 | E6: 3031 | F6: 1768 | G6: 1183 | H6: 1330 | I6: 1481 | J6: 1258 | K6: 1213 | M6: 347 | N6: 358 | O6: 373 | P6: 341 | Q6: 381 | R6: 367 | S6: =D6-(V6+U6+T6) -> 461 | T6: 477 | U6: 505 | V6: 530 | W6: 728 | X6: =F6-(AA6+Z6+Y6) -> 660 | Y6: 392 | Z6: 370 | AA6: 346 | AB6: =G6-(AE6+AD6+AC6) -> 337 | AC6: 274 | AD6: 301 | AE6: 271 | AF6: =H6-AG6-AH6-AI6 -> 262 | AG6: 333 | AH6: 389 | AI6: 346 | AJ6: =I6-AK6-AL6-AM6 -> 472 | AK6: 368 | AL6: 316 | AM6: 325
B7: פתרונות פוספט | C7: =O7+P7+Q7+R7 -> 2049 | D7: 2141 | E7: 2851 | F7: 2334 | G7: 1871 | H7: 1901 | I7: 2001 | J7: 1938 | K7: 2082 | M7: 589 | N7: 536 | O7: 475 | P7: 529 | Q7: 528 | R7: 517 | S7: =D7-(V7+U7+T7) -> 370 | T7: 559 | U7: 553 | V7: 659 | W7: 748 | X7: =F7-(AA7+Z7+Y7) -> 580 | Y7: 630 | Z7: 599 | AA7: 525 | AB7: =G7-(AE7+AD7+AC7) -> 479 | AC7: 488 | AD7: 421 | AE7: 483 | AF7: =H7-AG7-AH7-AI7 -> 400 | AG7: 491 | AH7: 496 | AI7: 514 | AJ7: =I7-AK7-AL7-AM7 -> 471 | AK7: 513 | AL7: 509 | AM7: 508
B8: מוצרים תעשייתיים | C8: =O8+P8+Q8+R8 -> 1220 | D8: 1206 | E8: 1737 | F8: 1601 | G8: 1242 | H8: 1307 | I8: 1281 | J8: 1179 | K8: 1111 | M8: 315 | N8: 338 | O8: 275 | P8: 305 | Q8: 309 | R8: 331 | S8: =D8-(V8+U8+T8) -> 294 | T8: 264 | U8: 297 | V8: 351 | W8: 488 | X8: =F8-(AA8+Z8+Y8) -> 418 | Y8: 383 | Z8: 406 | AA8: 394 | AB8: =G8-(AE8+AD8+AC8) -> 333 | AC8: 267 | AD8: 281 | AE8: 361 | AF8: =H8-AG8-AH8-AI8 -> 290 | AG8: 337 | AH8: 333 | AI8: 347 | AJ8: =I8-AK8-AL8-AM8 -> 316 | AK8: 325 | AL8: 326 | AM8: 314
B9: פתרונות חדשניים לחקלאות | C9: =O9+P9+Q9+R9 -> 1932 | D9: 2047 | E9: 2376 | F9: 1226 | G9: 715 | H9: 699 | I9: 719 | J9: 671 | K9: 632 | M9: 534 | N9: 491 | O9: 435 | P9: 534 | Q9: 489 | R9: 474 | S9: =D9-(V9+U9+T9) -> 475 | T9: 546 | U9: 473 | V9: 553 | W9: 556 | X9: =F9-(AA9+Z9+Y9) -> 374 | Y9: 379 | Z9: 235 | AA9: 238 | AB9: =G9-(AE9+AD9+AC9) -> 158 | AC9: 168 | AD9: 193 | AE9: 196 | AF9: =H9-AG9-AH9-AI9 -> 145 | AG9: 156 | AH9: 199 | AI9: 199 | AJ9: =I9-AK9-AL9-AM9 -> 142 | AK9: 157 | AL9: 209 | AM9: 211
B10: פעילויות אחרות | C10: =O10+P10+Q10+R10 -> 178 | D10: 169 | E10: 20 | F10: 26 | G10: 32 | H10: 34 | I10: 74 | J10: 372 | K10: 325 | M10: 47 | N10: 44 | O10: 43 | P10: 44 | Q10: 45 | R10: 46 | S10: =D10-(V10+U10+T10) -> 142 | T10: 16 | U10: 6 | V10: 5 | W10: 5 | X10: =F10-(AA10+Z10+Y10) -> 6 | Y10: 6 | Z10: 7 | AA10: 7 | AB10: =G10-(AE10+AD10+AC10) -> 10 | AC10: 7 | AD10: 7 | AE10: 8 | AF10: =H10-AG10-AH10-AI10 -> 9 | AG10: 8 | AH10: 8 | AI10: 9 | AJ10: =I10-AK10-AL10-AM10 -> 9 | AK10: 8 | AL10: 11 | AM10: 46
B11: התאמות | C11: =O11+P11+Q11+R11 -> 0 | D11: 0 | E11: 0 | F11: 0 | G11: 0 | H11: 0 | I11: 0 | J11: 0 | K11: 0 | M11: 0 | N11: 0 | O11: 0 | P11: 0 | Q11: 0 | R11: 0 | S11: =D11-(V11+U11+T11) -> 0 | T11: 0 | U11: 0 | V11: 0 | W11: 0 | X11: =F11-(AA11+Z11+Y11) -> 0 | Y11: 0 | Z11: 0 | AA11: 0 | AB11: =G11-(AE11+AD11+AC11) -> 0 | AC11: 0 | AD11: 0 | AE11: 0 | AF11: =H11-AG11-AH11-AI11 -> 0 | AG11: 0 | AH11: 0 | AI11: 0 | AJ11: =I11-AK11-AL11-AM11 -> 0 | AK11: 0 | AL11: 0 | AM11: 0
B12: סה"כ | C12: =SUM(C6:C11) -> 6841 | D12: =SUM(D6:D11) -> 7536 | E12: =SUM(E6:E11) -> 10015 | F12: =SUM(F6:F11) -> 6955 | G12: =SUM(G6:G11) -> 5043 | H12: =SUM(H6:H11) -> 5271 | I12: =SUM(I6:I11) -> 5556 | J12: =SUM(J6:J11) -> 5418 | K12: =SUM(K6:K11) -> 5363 | M12: =SUM(M6:M11) -> 1832 | N12: =SUM(N6:N11) -> 1767 | O12: =SUM(O6:O11) -> 1601 | P12: =SUM(P6:P11) -> 1753 | Q12: =SUM(Q6:Q11) -> 1752 | R12: =SUM(R6:R11) -> 1735 | S12: =SUM(S6:S11) -> 1742 | T12: =SUM(T6:T11) -> 1862 | ... AM12: =SUM(AM6:AM11) -> 1404
B13: בדיקה | C13: ='IC&CF&BS'!C3-C12 -> 0 | D13: ='IC&CF&BS'!D3-D12 -> 0 | E13: ='IC&CF&BS'!E3-E12 -> 0 | F13: ='IC&CF&BS'!F3-F12 -> 0 | G13: ='IC&CF&BS'!G3-G12 -> 0 | H13: ='IC&CF&BS'!H3-H12 -> 0 | I13: ='IC&CF&BS'!I3-I12 -> 0 | J13: ='IC&CF&BS'!J3-J12 -> 0 | K13: ='IC&CF&BS'!K3-K12 -> 0 | M13: ='IC&CF&BS'!O3-M12 -> 0 | N13: ='IC&CF&BS'!P3-N12 -> 0 | O13: ='IC&CF&BS'!Q3-O12 -> 0 | P13: ='IC&CF&BS'!R3-P12 -> 0 | Q13: ='IC&CF&BS'!S3-Q12 -> 0 | R13: ='IC&CF&BS'!T3-R12 -> 0 | S13: ='IC&CF&BS'!U3-S12 -> 0 | T13: ='IC&CF&BS'!V3-T12 -> 0 | ... V13: ='IC&CF&BS'!X3-V12 -> 0 | W13: ='IC&CF&BS'!AB3-W12 -> 0 | X13: ='IC&CF&BS'!AC3-X12 -> 0 | Y13: ='IC&CF&BS'!AD3-Y12 -> 0 | Z13: ='IC&CF&BS'!AE3-Z12 -> 0 | AA13: ='IC&CF&BS'!AF3-AA12 -> 0 | AB13: ='IC&CF&BS'!AG3-AB12 -> 0 | AC13: ='IC&CF&BS'!AH3-AC12 -> 0 | AD13: ='IC&CF&BS'!AI3-AD12 -> 0 | ... AM13: ='IC&CF&BS'!AR3-AM12 -> 0
B15: שיעור מסך הכנסות
B16: אשלג | C16: =IFERROR(C6/C$12,"") -> 0.21371145 | D16: =IFERROR(D6/D$12,"") -> 0.26180998 | E16: =IFERROR(E6/E$12,"") -> 0.30264603 | F16: =IFERROR(F6/F$12,"") -> 0.25420561 | G16: =IFERROR(G6/G$12,"") -> 0.23458259 | H16: =IFERROR(H6/H$12,"") -> 0.25232404 | I16: =IFERROR(I6/I$12,"") -> 0.26655868 | J16: =IFERROR(J6/J$12,"") -> 0.232189 | K16: =IFERROR(K6/K$12,"") -> 0.22617938 | M16: =IFERROR(M6/M$12,"") -> 0.18941048 | N16: =IFERROR(N6/N$12,"") -> 0.20260328 | O16: =IFERROR(O6/O$12,"") -> 0.23297939 | P16: =IFERROR(P6/P$12,"") -> 0.19452367 | Q16: =IFERROR(Q6/Q$12,"") -> 0.21746575 | R16: =IFERROR(R6/R$12,"") -> 0.21152738 | S16: =IFERROR(S6/S$12,"") -> 0.26463835 | T16: =IFERROR(T6/T$12,"") -> 0.25617615 | ... AM16: =IFERROR(AM6/AM$12,"") -> 0.23148148
B17: פתרונות פוספט | C17: =IFERROR(C7/C$12,"") -> 0.29951761 | D17: =IFERROR(D7/D$12,"") -> 0.28410297 | E17: =IFERROR(E7/E$12,"") -> 0.28467299 | F17: =IFERROR(F7/F$12,"") -> 0.33558591 | G17: =IFERROR(G7/G$12,"") -> 0.37100932 | H17: =IFERROR(H7/H$12,"") -> 0.36065263 | I17: =IFERROR(I7/I$12,"") -> 0.36015119 | J17: =IFERROR(J7/J$12,"") -> 0.35769657 | K17: =IFERROR(K7/K$12,"") -> 0.38821555 | M17: =IFERROR(M7/M$12,"") -> 0.32150655 | N17: =IFERROR(N7/N$12,"") -> 0.30333899 | O17: =IFERROR(O7/O$12,"") -> 0.29668957 | P17: =IFERROR(P7/P$12,"") -> 0.3017684 | Q17: =IFERROR(Q7/Q$12,"") -> 0.30136986 | R17: =IFERROR(R7/R$12,"") -> 0.29798271 | S17: =IFERROR(S7/S$12,"") -> 0.21239954 | T17: =IFERROR(T7/T$12,"") -> 0.30021482 | ... AM17: =IFERROR(AM7/AM$12,"") -> 0.36182336
B18: מוצרים תעשייתיים | C18: =IFERROR(C8/C$12,"") -> 0.1783365 | D18: =IFERROR(D8/D$12,"") -> 0.16003185 | E18: =IFERROR(E8/E$12,"") -> 0.17343984 | F18: =IFERROR(F8/F$12,"") -> 0.2301941 | G18: =IFERROR(G8/G$12,"") -> 0.24628198 | H18: =IFERROR(H8/H$12,"") -> 0.24796054 | I18: =IFERROR(I8/I$12,"") -> 0.23056156 | J18: =IFERROR(J8/J$12,"") -> 0.21760797 | K18: =IFERROR(K8/K$12,"") -> 0.20716017 | M18: =IFERROR(M8/M$12,"") -> 0.17194323 | N18: =IFERROR(N8/N$12,"") -> 0.19128466 | O18: =IFERROR(O8/O$12,"") -> 0.17176765 | P18: =IFERROR(P8/P$12,"") -> 0.17398745 | Q18: =IFERROR(Q8/Q$12,"") -> 0.17636986 | R18: =IFERROR(R8/R$12,"") -> 0.1907781 | S18: =IFERROR(S8/S$12,"") -> 0.16877153 | T18: =IFERROR(T8/T$12,"") -> 0.14178303 | ... AM18: =IFERROR(AM8/AM$12,"") -> 0.22364672
B19: פתרונות חדשניים לחקלאות | C19: =IFERROR(C9/C$12,"") -> 0.28241485 | D19: =IFERROR(D9/D$12,"") -> 0.27162951 | E19: =IFERROR(E9/E$12,"") -> 0.23724413 | F19: =IFERROR(F9/F$12,"") -> 0.17627606 | G19: =IFERROR(G9/G$12,"") -> 0.14178069 | H19: =IFERROR(H9/H$12,"") -> 0.13261241 | I19: =IFERROR(I9/I$12,"") -> 0.12940965 | J19: =IFERROR(J9/J$12,"") -> 0.12384644 | K19: =IFERROR(K9/K$12,"") -> 0.11784449 | M19: =IFERROR(M9/M$12,"") -> 0.29148472 | N19: =IFERROR(N9/N$12,"") -> 0.2778721 | O19: =IFERROR(O9/O$12,"") -> 0.27170518 | P19: =IFERROR(P9/P$12,"") -> 0.30462065 | Q19: =IFERROR(Q9/Q$12,"") -> 0.27910959 | R19: =IFERROR(R9/R$12,"") -> 0.27319885 | S19: =IFERROR(S9/S$12,"") -> 0.27267509 | T19: =IFERROR(T9/T$12,"") -> 0.29323308 | ... AM19: =IFERROR(AM9/AM$12,"") -> 0.1502849
B20: פעילויות אחרות | C20: =IFERROR(C10/C$12,"") -> 0.026019588 | D20: =IFERROR(D10/D$12,"") -> 0.02242569 | E20: =IFERROR(E10/E$12,"") -> 0.0019970045 | F20: =IFERROR(F10/F$12,"") -> 0.0037383178 | G20: =IFERROR(G10/G$12,"") -> 0.0063454293 | H20: =IFERROR(H10/H$12,"") -> 0.0064503889 | I20: =IFERROR(I10/I$12,"") -> 0.013318934 | J20: =IFERROR(J10/J$12,"") -> 0.068660022 | K20: =IFERROR(K10/K$12,"") -> 0.06060041 | M20: =IFERROR(M10/M$12,"") -> 0.025655022 | N20: =IFERROR(N10/N$12,"") -> 0.024900962 | O20: =IFERROR(O10/O$12,"") -> 0.026858214 | P20: =IFERROR(P10/P$12,"") -> 0.025099829 | Q20: =IFERROR(Q10/Q$12,"") -> 0.025684932 | R20: =IFERROR(R10/R$12,"") -> 0.026512968 | S20: =IFERROR(S10/S$12,"") -> 0.081515499 | T20: =IFERROR(T10/T$12,"") -> 0.0085929108 | ... AM20: =IFERROR(AM10/AM$12,"") -> 0.032763533
B21: התאמות
B23: צמיחה שנתית
B24: אשלג | C24: =IFERROR(C6/D6-1,"") -> -0.25899645 | D24: =IFERROR(D6/E6-1,"") -> -0.34905972 | E24: =IFERROR(E6/F6-1,"") -> 0.71436652 | F24: =IFERROR(F6/G6-1,"") -> 0.49450549 | G24: =IFERROR(G6/H6-1,"") -> -0.11052632 | H24: =IFERROR(H6/I6-1,"") -> -0.10195814 | I24: =IFERROR(I6/J6-1,"") -> 0.1772655 | J24: =IFERROR(J6/K6-1,"") -> 0.037098104 | K24: =IFERROR(K6/#REF!-1,"") | M24: =IFERROR(M6/N6-1,"") -> -0.030726257 | N24: =IFERROR(N6/O6-1,"") -> -0.040214477 | O24: =IFERROR(O6/P6-1,"") -> 0.093841642 | P24: =IFERROR(P6/Q6-1,"") -> -0.10498688 | Q24: =IFERROR(Q6/R6-1,"") -> 0.038147139 | R24: =IFERROR(R6/S6-1,"") -> -0.20390456 | S24: =IFERROR(S6/T6-1,"") -> -0.033542977 | T24: =IFERROR(T6/U6-1,"") -> -0.055445545 | ... AM24: =IFERROR(AM6/AN6-1,"")
B25: פתרונות פוספט | C25: =IFERROR(C7/D7-1,"") -> -0.042970574 | D25: =IFERROR(D7/E7-1,"") -> -0.24903543 | E25: =IFERROR(E7/F7-1,"") -> 0.22150814 | F25: =IFERROR(F7/G7-1,"") -> 0.24746125 | G25: =IFERROR(G7/H7-1,"") -> -0.015781168 | H25: =IFERROR(H7/I7-1,"") -> -0.049975012 | I25: =IFERROR(I7/J7-1,"") -> 0.03250774 | J25: =IFERROR(J7/K7-1,"") -> -0.069164265 | K25: =IFERROR(K7/#REF!-1,"") | M25: =IFERROR(M7/N7-1,"") -> 0.098880597 | N25: =IFERROR(N7/O7-1,"") -> 0.12842105 | O25: =IFERROR(O7/P7-1,"") -> -0.1020794 | P25: =IFERROR(P7/Q7-1,"") -> 0.0018939394 | Q25: =IFERROR(Q7/R7-1,"") -> 0.021276596 | R25: =IFERROR(R7/S7-1,"") -> 0.3972973 | S25: =IFERROR(S7/T7-1,"") -> -0.33810376 | T25: =IFERROR(T7/U7-1,"") -> 0.01084991 | ... AM25: =IFERROR(AM7/AN7-1,"")
B26: מוצרים תעשייתיים | C26: =IFERROR(C8/D8-1,"") -> 0.011608624 | D26: =IFERROR(D8/E8-1,"") -> -0.30569948 | E26: =IFERROR(E8/F8-1,"") -> 0.084946908 | F26: =IFERROR(F8/G8-1,"") -> 0.28904992 | G26: =IFERROR(G8/H8-1,"") -> -0.049732211 | H26: =IFERROR(H8/I8-1,"") -> 0.020296643 | I26: =IFERROR(I8/J8-1,"") -> 0.086513995 | J26: =IFERROR(J8/K8-1,"") -> 0.061206121 | K26: =IFERROR(K8/#REF!-1,"") | M26: =IFERROR(M8/N8-1,"") -> -0.068047337 | N26: =IFERROR(N8/O8-1,"") -> 0.22909091 | O26: =IFERROR(O8/P8-1,"") -> -0.098360656 | P26: =IFERROR(P8/Q8-1,"") -> -0.012944984 | Q26: =IFERROR(Q8/R8-1,"") -> -0.066465257 | R26: =IFERROR(R8/S8-1,"") -> 0.12585034 | S26: =IFERROR(S8/T8-1,"") -> 0.11363636 | T26: =IFERROR(T8/U8-1,"") -> -0.11111111 | ... AM26: =IFERROR(AM8/AN8-1,"")
B27: פתרונות חדשניים לחקלאות | C27: =IFERROR(C9/D9-1,"") -> -0.056179775 | D27: =IFERROR(D9/E9-1,"") -> -0.13846801 | E27: =IFERROR(E9/F9-1,"") -> 0.93800979 | F27: =IFERROR(F9/G9-1,"") -> 0.71468531 | G27: =IFERROR(G9/H9-1,"") -> 0.022889843 | H27: =IFERROR(H9/I9-1,"") -> -0.027816412 | I27: =IFERROR(I9/J9-1,"") -> 0.071535022 | J27: =IFERROR(J9/K9-1,"") -> 0.061708861 | K27: =IFERROR(K9/#REF!-1,"") | M27: =IFERROR(M9/N9-1,"") -> 0.087576375 | N27: =IFERROR(N9/O9-1,"") -> 0.12873563 | O27: =IFERROR(O9/P9-1,"") -> -0.18539326 | P27: =IFERROR(P9/Q9-1,"") -> 0.09202454 | Q27: =IFERROR(Q9/R9-1,"") -> 0.03164557 | R27: =IFERROR(R9/S9-1,"") -> -0.0021052632 | S27: =IFERROR(S9/T9-1,"") -> -0.13003663 | T27: =IFERROR(T9/U9-1,"") -> 0.15433404 | ... AM27: =IFERROR(AM9/AN9-1,"")
B28: פעילויות אחרות | C28: =IFERROR(C10/D10-1,"") -> 0.053254438 | D28: =IFERROR(D10/E10-1,"") -> 7.45 | E28: =IFERROR(E10/F10-1,"") -> -0.23076923 | F28: =IFERROR(F10/G10-1,"") -> -0.1875 | G28: =IFERROR(G10/H10-1,"") -> -0.058823529 | H28: =IFERROR(H10/I10-1,"") -> -0.54054054 | I28: =IFERROR(I10/J10-1,"") -> -0.80107527 | J28: =IFERROR(J10/K10-1,"") -> 0.14461538 | K28: =IFERROR(K10/#REF!-1,"") | M28: =IFERROR(M10/N10-1,"") -> 0.068181818 | N28: =IFERROR(N10/O10-1,"") -> 0.023255814 | O28: =IFERROR(O10/P10-1,"") -> -0.022727273 | P28: =IFERROR(P10/Q10-1,"") -> -0.022222222 | Q28: =IFERROR(Q10/R10-1,"") -> -0.02173913 | R28: =IFERROR(R10/S10-1,"") -> -0.67605634 | S28: =IFERROR(S10/T10-1,"") -> 7.875 | T28: =IFERROR(T10/U10-1,"") -> 1.6666667 | ... AM28: =IFERROR(AM10/AN10-1,"")
B29: התאמות | C29: =IFERROR(C11/D11-1,"") | D29: =IFERROR(D11/E11-1,"") | E29: =IFERROR(E11/F11-1,"") | F29: =IFERROR(F11/G11-1,"") | G29: =IFERROR(G11/H11-1,"") | H29: =IFERROR(H11/I11-1,"") | I29: =IFERROR(I11/J11-1,"") | J29: =IFERROR(J11/K11-1,"") | K29: =IFERROR(K11/#REF!-1,"") | M29: =IFERROR(M11/N11-1,"") | N29: =IFERROR(N11/O11-1,"") | O29: =IFERROR(O11/P11-1,"") | P29: =IFERROR(P11/Q11-1,"") | Q29: =IFERROR(Q11/R11-1,"") | R29: =IFERROR(R11/S11-1,"") | S29: =IFERROR(S11/T11-1,"") | T29: =IFERROR(T11/U11-1,"") | ... AM29: =IFERROR(AM11/AN11-1,"")
B30: סה"כ | C30: =IFERROR(C12/D12-1,"") -> -0.092223992 | D30: =IFERROR(D12/E12-1,"") -> -0.24752871 | E30: =IFERROR(E12/F12-1,"") -> 0.43997124 | F30: =IFERROR(F12/G12-1,"") -> 0.3791394 | G30: =IFERROR(G12/H12-1,"") -> -0.043255549 | H30: =IFERROR(H12/I12-1,"") -> -0.051295896 | I30: =IFERROR(I12/J12-1,"") -> 0.025470653 | J30: =IFERROR(J12/K12-1,"") -> 0.010255454 | K30: =IFERROR(K12/#REF!-1,"") | M30: =IFERROR(M12/N12-1,"") -> 0.036785512 | N30: =IFERROR(N12/O12-1,"") -> 0.1036852 | O30: =IFERROR(O12/P12-1,"") -> -0.0867085 | P30: =IFERROR(P12/Q12-1,"") -> 0.00057077626 | Q30: =IFERROR(Q12/R12-1,"") -> 0.0097982709 | R30: =IFERROR(R12/S12-1,"") -> -0.0040183697 | S30: =IFERROR(S12/T12-1,"") -> -0.064446831 | T30: =IFERROR(T12/U12-1,"") -> 0.015267176 | ... AM30: =IFERROR(AM12/AN12-1,"")
B32: רווח (הפסד) מגזרי
B33: אשלג | C33: =O33+P33+Q33+R33 -> 250 | D33: 668 | E33: 1822 | F33: 399 | G33: 120 | H33: 289 | I33: 315 | J33: 198 | K33: 245 | M33: 52 | N33: 56 | O33: 69 | P33: 59 | Q33: 60 | R33: 62 | S33: =D33-(V33+U33+T33) -> 122 | T33: 125 | U33: 167 | V33: 254 | W33: 410 | X33: =F33-(AA33+Z33+Y33) -> 244 | Y33: 83 | Z33: 43 | AA33: 29 | AB33: =G33-(AE33+AD33+AC33) -> 40 | AC33: 28 | AD33: 38 | AE33: 14 | AF33: =H33-AG33-AH33-AI33 -> 22 | AG33: 83 | AH33: 105 | AI33: 79 | AJ33: =I33-AK33-AL33-AM33 -> 138 | AK33: 78 | AL33: 56 | AM33: 43 | AO33: =K33 -> 245 | AP33: =AO33/$AO$39 -> 0.41315346 | AQ33: =AP33*$AO$40 -> -132.62226 | AR33: =AO33+AQ33 -> 112.37774
B34: פתרונות פוספט | C34: =O34+P34+Q34+R34 -> 358 | D34: 350 | E34: 777 | F34: 307 | G34: 66 | H34: 100 | I34: 113 | J34: 53 | K34: 75 | M34: 90 | N34: 91 | O34: 81 | P34: 100 | Q34: 93 | R34: 84 | S34: =D34-(V34+U34+T34) -> 95 | T34: 69 | U34: 71 | V34: 115 | W34: 200 | X34: =F34-(AA34+Z34+Y34) -> 97 | Y34: 93 | Z34: 77 | AA34: 40 | AB34: =G34-(AE34+AD34+AC34) -> 21 | AC34: 28 | AD34: 8 | AE34: 9 | AF34: =H34-AG34-AH34-AI34 -> 1 | AG34: 32 | AH34: 32 | AI34: 35 | AJ34: =I34-AK34-AL34-AM34 -> 14 | AK34: 40 | AL34: 31 | AM34: 28 | AO34: =K34 -> 75 | AP34: =AO34/$AO$39 -> 0.12647555 | AQ34: =AP34*$AO$40 -> -40.598651 | AR34: =AO34+AQ34 -> 34.401349
B35: מוצרים תעשייתיים | C35: =O35+P35+Q35+R35 -> 224 | D35: 220 | E35: 628 | F35: 435 | G35: 303 | H35: 338 | I35: 300 | J35: 247 | K35: 241 | M35: 54 | N35: 62 | O35: 55 | P35: 50 | Q35: 60 | R35: 59 | S35: =D35-(V35+U35+T35) -> 39 | T35: 31 | U35: 60 | V35: 90 | W35: 188 | X35: =F35-(AA35+Z35+Y35) -> 111 | Y35: 105 | Z35: 114 | AA35: 105 | AB35: =G35-(AE35+AD35+AC35) -> 80 | AC35: 50 | AD35: 70 | AE35: 103 | AF35: =H35-AG35-AH35-AI35 -> 60 | AG35: 88 | AH35: 93 | AI35: 97 | AJ35: =I35-AK35-AL35-AM35 -> 70 | AK35: 83 | AL35: 81 | AM35: 66 | AO35: =K35 -> 241 | AP35: =AO35/$AO$39 -> 0.40640809 | AQ35: =AP35*$AO$40 -> -130.457 | AR35: =AO35+AQ35 -> 110.543
B36: פתרונות חדשניים לחקלאות | C36: =O36+P36+Q36+R36 -> 128 | D36: 51 | E36: 378 | F36: 121 | G36: 40 | H36: 21 | I36: 29 | J36: 29 | K36: 28 | M36: 35 | N36: 28 | O36: 31 | P36: 49 | Q36: 25 | R36: 23 | S36: =D36-(V36+U36+T36) -> -5 | T36: 20 | U36: 4 | V36: 32 | W36: 93 | X36: =F36-(AA36+Z36+Y36) -> 33 | Y36: 46 | Z36: 20 | AA36: 22 | AB36: =G36-(AE36+AD36+AC36) -> 5 | AC36: 6 | AD36: 15 | AE36: 14 | AF36: =H36-AG36-AH36-AI36 -> -2 | AG36: -2 | AH36: 12 | AI36: 13 | AJ36: =I36-AK36-AL36-AM36 -> -4 | AK36: -1 | AL36: 16 | AM36: 18 | AO36: =K36 -> 28 | AP36: =AO36/$AO$39 -> 0.047217538 | AQ36: =AP36*$AO$40 -> -15.15683 | AR36: =AO36+AQ36 -> 12.84317
B37: פעילויות אחרות | C37: =O37+P37+Q37+R37 -> -22 | D37: -34 | E37: -9 | F37: -8 | G37: -5 | H37: 19 | I37: 9 | J37: 127 | K37: 41 | M37: -2 | N37: -3 | O37: -8 | P37: -7 | Q37: -4 | R37: -3 | S37: =D37-(V37+U37+T37) -> -22 | T37: -7 | U37: -3 | V37: -2 | W37: -3 | X37: =F37-(AA37+Z37+Y37) -> -1 | Y37: -3 | Z37: -2 | AA37: -2 | AB37: =G37-(AE37+AD37+AC37) -> -2 | AC37: -1 | AD37: -2 | AE37: 0 | AF37: =H37-AG37-AH37-AI37 -> 2 | AG37: 5 | AH37: -1 | AI37: 13 | AJ37: =I37-AK37-AL37-AM37 -> 0 | AK37: 1 | AL37: 2 | AM37: 6 | AO37: =K37 -> 41 | AP37: =AO37/$AO$39 -> 0.069139966 | AQ37: =AP37*$AO$40 -> -22.193929 | AR37: =AO37+AQ37 -> 18.806071
B38: התאמות | C38: =O38+P38+Q38+R38 -> -65 | D38: -37 | E38: -87 | F38: -60 | G38: -15 | H38: -7 | I38: -13 | J38: -2 | K38: -37 | M38: -28 | N38: -26 | O38: -38 | P38: -8 | Q38: -9 | R38: -10 | S38: =D38-(V38+U38+T38) -> -18 | T38: -11 | U38: 1 | V38: -9 | W38: -8 | X38: =F38-(AA38+Z38+Y38) -> -26 | Y38: -9 | Z38: -16 | AA38: -9 | AB38: =G38-(AE38+AD38+AC38) -> -1 | AC38: -5 | AD38: -1 | AE38: -8 | AF38: =H38-AG38-AH38-AI38 -> 5 | AG38: -5 | AH38: -11 | AI38: 4 | AJ38: =I38-AK38-AL38-AM38 -> -4 | AK38: -1 | AL38: 2 | AM38: -10 | AO38: =K38 -> -37 | AP38: =AO38/$AO$39 -> -0.062394604 | AQ38: =AP38*$AO$40 -> 20.028668 | AR38: =AO38+AQ38 -> -16.971332
B39: סה"כ רווח מגזרי כולל חלק החברה ברווח של שותפויות בשליטה משותפת | C39: =SUM(C33:C38) -> 873 | D39: =SUM(D33:D38) -> 1218 | E39: =SUM(E33:E38) -> 3509 | F39: =SUM(F33:F38) -> 1194 | G39: =SUM(G33:G38) -> 509 | H39: =SUM(H33:H38) -> 760 | I39: =SUM(I33:I38) -> 753 | J39: =SUM(J33:J38) -> 652 | K39: =SUM(K33:K38) -> 593 | M39: =SUM(M33:M38) -> 201 | N39: =SUM(N33:N38) -> 208 | O39: =SUM(O33:O38) -> 190 | P39: =SUM(P33:P38) -> 243 | Q39: =SUM(Q33:Q38) -> 225 | R39: =SUM(R33:R38) -> 215 | S39: =SUM(S33:S38) -> 211 | T39: =SUM(T33:T38) -> 227 | ... AM39: =SUM(AM33:AM38) -> 151 | AO39: =SUM(AO33:AO38) -> 593 | AP39: =AO39/$AO$39 -> 1 | AQ39: =AP39*$AO$40 -> -321 | AR39: =SUM(AR33:AR38) -> 272
B40: הוצאות לא משוייכות | C40: =O40+P40+Q40+R40 -> -98 | D40: -77 | E40: 7 | F40: 16 | G40: -307 | H40: -4 | I40: 766 | J40: -23 | K40: -323 | M40: -20 | N40: -23 | O40: -43 | P40: -29 | Q40: -14 | R40: -12 | S40: =D40-(V40+U40+T40) -> -62 | T40: 0 | U40: 0 | V40: -15 | W40: 22 | X40: =F40-(AA40+Z40+Y40) -> 3 | Y40: 6 | Z40: 7 | AA40: 0 | AB40: =G40-(AE40+AD40+AC40) -> -4 | AC40: -6 | AD40: -297 | AE40: 0 | AF40: 0 | AG40: 0 | AH40: 10 | AI40: -14 | AJ40: =I40-AK40-AL40-AM40 -> -48 | AK40: -4 | AL40: -16 | AM40: 834 | AO40: -321
B41: רווח תפעולי לפני אחרות | C41: =SUM(C39:C40) -> 775 | D41: =SUM(D39:D40) -> 1141 | E41: =SUM(E39:E40) -> 3516 | F41: =SUM(F39:F40) -> 1210 | G41: =SUM(G39:G40) -> 202 | H41: =SUM(H39:H40) -> 756 | I41: =SUM(I39:I40) -> 1519 | J41: =SUM(J39:J40) -> 629 | K41: =SUM(K39:K40) -> 270 | M41: =SUM(M39:M40) -> 181 | N41: =SUM(N39:N40) -> 185 | O41: =SUM(O39:O40) -> 147 | P41: =SUM(P39:P40) -> 214 | Q41: =SUM(Q39:Q40) -> 211 | R41: =SUM(R39:R40) -> 203 | S41: =SUM(S39:S40) -> 149 | T41: =SUM(T39:T40) -> 227 | ... AM41: =SUM(AM39:AM40) -> 985
C42: ='IC&CF&BS'!C9+'IC&CF&BS'!C10-C41 -> 0 | D42: ='IC&CF&BS'!D9+'IC&CF&BS'!D10-D41 -> 0 | E42: ='IC&CF&BS'!E9+'IC&CF&BS'!E10-E41 -> 0 | F42: ='IC&CF&BS'!F9+'IC&CF&BS'!F10-F41 -> 0 | G42: ='IC&CF&BS'!G9+'IC&CF&BS'!G10-G41 -> 0 | H42: ='IC&CF&BS'!H9+'IC&CF&BS'!H10-H41 -> 0 | I42: ='IC&CF&BS'!I9+'IC&CF&BS'!I10-I41 -> 0 | J42: ='IC&CF&BS'!J9+'IC&CF&BS'!J10-J41 -> 0 | K42: ='IC&CF&BS'!K9+'IC&CF&BS'!K10 -> -3 | M42: ='IC&CF&BS'!O9+'IC&CF&BS'!O10-M41 -> 0 | N42: ='IC&CF&BS'!P9+'IC&CF&BS'!P10-N41 -> 0 | O42: ='IC&CF&BS'!Q9+'IC&CF&BS'!Q10-O41 -> 0 | P42: ='IC&CF&BS'!R9+'IC&CF&BS'!R10-P41 -> 0 | Q42: ='IC&CF&BS'!S9+'IC&CF&BS'!S10-Q41 -> 0 | R42: ='IC&CF&BS'!T9+'IC&CF&BS'!T10-R41 -> 0 | S42: ='IC&CF&BS'!U9+'IC&CF&BS'!U10-S41 -> 0 | T42: ='IC&CF&BS'!V9+'IC&CF&BS'!V10-T41 -> 0 | ... V42: ='IC&CF&BS'!X9+'IC&CF&BS'!X10-V41 -> 0 | W42: ='IC&CF&BS'!AB9+'IC&CF&BS'!AB10-W41 -> 0 | X42: ='IC&CF&BS'!AC9+'IC&CF&BS'!AC10-X41 -> 0 | Y42: ='IC&CF&BS'!AD9+'IC&CF&BS'!AD10-Y41 -> 0 | Z42: ='IC&CF&BS'!AE9+'IC&CF&BS'!AE10-Z41 -> 0 | AA42: ='IC&CF&BS'!AF9+'IC&CF&BS'!AF10-AA41 -> 0 | AB42: ='IC&CF&BS'!AG9+'IC&CF&BS'!AG10-AB41 -> 0 | AC42: ='IC&CF&BS'!AH9+'IC&CF&BS'!AH10-AC41 -> 0 | AD42: ='IC&CF&BS'!AI9+'IC&CF&BS'!AI10-AD41 -> 0 | ... AM42: ='IC&CF&BS'!AR9+'IC&CF&BS'!AR10-AM41 -> 0
B43: שיעור הרווח התפעולי (מגזרי)
B44: אשלג | C44: =IFERROR(C33/C6,"") -> 0.17099863 | D44: =IFERROR(D33/D6,"") -> 0.3385707 | E44: =IFERROR(E33/E6,"") -> 0.60112174 | F44: =IFERROR(F33/F6,"") -> 0.22567873 | G44: =IFERROR(G33/G6,"") -> 0.10143702 | H44: =IFERROR(H33/H6,"") -> 0.21729323 | I44: =IFERROR(I33/I6,"") -> 0.21269413 | J44: =IFERROR(J33/J6,"") -> 0.15739269 | K44: =IFERROR(K33/K6,"") -> 0.20197857 | M44: =IFERROR(M33/M6,"") -> 0.14985591 | N44: =IFERROR(N33/N6,"") -> 0.15642458 | O44: =IFERROR(O33/O6,"") -> 0.1849866 | P44: =IFERROR(P33/P6,"") -> 0.17302053 | Q44: =IFERROR(Q33/Q6,"") -> 0.15748031 | R44: =IFERROR(R33/R6,"") -> 0.16893733 | S44: =IFERROR(S33/S6,"") -> 0.26464208 | T44: =IFERROR(T33/T6,"") -> 0.26205451 | ... AM44: =IFERROR(AM33/AM6,"") -> 0.13230769
B45: פתרונות פוספט | C45: =IFERROR(C34/C7,"") -> 0.17471938 | D45: =IFERROR(D34/D7,"") -> 0.16347501 | E45: =IFERROR(E34/E7,"") -> 0.27253595 | F45: =IFERROR(F34/F7,"") -> 0.13153385 | G45: =IFERROR(G34/G7,"") -> 0.035275254 | H45: =IFERROR(H34/H7,"") -> 0.052603893 | I45: =IFERROR(I34/I7,"") -> 0.056471764 | J45: =IFERROR(J34/J7,"") -> 0.027347781 | K45: =IFERROR(K34/K7,"") -> 0.036023055 | M45: =IFERROR(M34/M7,"") -> 0.15280136 | N45: =IFERROR(N34/N7,"") -> 0.16977612 | O45: =IFERROR(O34/O7,"") -> 0.17052632 | P45: =IFERROR(P34/P7,"") -> 0.18903592 | Q45: =IFERROR(Q34/Q7,"") -> 0.17613636 | R45: =IFERROR(R34/R7,"") -> 0.16247582 | S45: =IFERROR(S34/S7,"") -> 0.25675676 | T45: =IFERROR(T34/T7,"") -> 0.1234347 | ... AM45: =IFERROR(AM34/AM7,"") -> 0.05511811
B46: מוצרים תעשייתיים | C46: =IFERROR(C35/C8,"") -> 0.18360656 | D46: =IFERROR(D35/D8,"") -> 0.18242123 | E46: =IFERROR(E35/E8,"") -> 0.36154289 | F46: =IFERROR(F35/F8,"") -> 0.27170518 | G46: =IFERROR(G35/G8,"") -> 0.24396135 | H46: =IFERROR(H35/H8,"") -> 0.2586075 | I46: =IFERROR(I35/I8,"") -> 0.23419204 | J46: =IFERROR(J35/J8,"") -> 0.20949958 | K46: =IFERROR(K35/K8,"") -> 0.21692169 | M46: =IFERROR(M35/M8,"") -> 0.17142857 | N46: =IFERROR(N35/N8,"") -> 0.18343195 | O46: =IFERROR(O35/O8,"") -> 0.2 | P46: =IFERROR(P35/P8,"") -> 0.16393443 | Q46: =IFERROR(Q35/Q8,"") -> 0.19417476 | R46: =IFERROR(R35/R8,"") -> 0.17824773 | S46: =IFERROR(S35/S8,"") -> 0.13265306 | T46: =IFERROR(T35/T8,"") -> 0.11742424 | ... AM46: =IFERROR(AM35/AM8,"") -> 0.21019108
...

Sheet DCF 1.6.2025
A2: הערכת שווי איי.סי.אל
A3: שנה סעיף | B3: 1999A | C3: 2000A | D3: 2001A | E3: 2002A | F3: 2003A | G3: 2004A | H3: 2006A | I3: 2005A | J3: 2006A | K3: 2007A | L3: 2008A | M3: 2009A | N3: Q1-10A | O3: Q2-10A | P3: Q3-10A | Q3: Q4-10A | R3: 2010A | S3: Q1-11A | T3: Q2-11A | U3: Q3-11A | V3: Q4-11A | W3: 2011A | X3: Q1-12A | Y3: Q2-12A | Z3: Q3-12A | AA3: Q4-12A | AB3: 2012A | AC3: Q1-13A | AD3: Q2-13A | AE3: Q3-13A | AF3: Q4-13A | AG3: 2013A | AH3: 2016A | AI3: 2017A | AJ3: 2018A | AK3: 2019A | AL3: 2020A | AM3: 2021A | AN3: Q1-22A | AO3: 2022A | AP3: Q1-23A | AQ3: Q2-23A | AR3: Q3-23A | AS3: Q4-23E | AT3: 2023A | AU3: Q1-24A | AV3: Q2-24A | AW3: Q3-24A | AX3: Q4-24A | AY3: 2024A | AZ3: Q1-25A | BA3: Q2-25A | BB3: H2-25E | BC3: 2025E | BD3: 2026E | BE3: 2027E | BG3: ביחס ל- 2023
AE4: מ' $
A5: הכנסות:
