Workbook

Sheet Monthly_Board_Pack
B2: PROJECT PATRY
B4: MONTHLY BOARD PACK
B6: =TEXT(DATE(YEAR(TODAY()),MONTH(TODAY()),1),"mmmm yyyy") -> January 2026
B8: Prepared for: Board of Directors
B10: ="Generated: "&TEXT(NOW(),"mmmm d, yyyy")&" at "&TEXT(NOW(),"h:mm AM/PM") -> Generated: January 12, 2026 at 9:41 AM
B14: 1. EXECUTIVE SUMMARY
B16: Total Revenue | D16: Net Operating Income | F16: NOI Margin | H16: Portfolio Occupancy | J16: FFO | L16: Debt Service Coverage
B17: {=CAP_21_Investor_Quarterly!B5} -> 13350000 | D17: {=FIN_01_Investor_Pack!E21} -> 7715000 | F17: {=CAP_21_Investor_Quarterly!B7} -> 0.614 | H17: {=OPS_11_Occupancy_Mix!D12} -> 0.95219124 | J17: {=CAP_21_Investor_Quarterly!B10} -> 7050000 | L17: {=FIN_07_Debt_Covenant!D5} -> 1.52
B18: {=CAP_21_Investor_Quarterly!D5} -> 0.019083969 | D18: vs Q3: +2.1% | F18: vs Plan: +0.4% | H18: vs Plan: +1.2% | J18: {=CAP_21_Investor_Quarterly!D10} -> 0.02173913 | L18: ✓ All Pass
B20: 2. PORTFOLIO PERFORMANCE
B22: FINANCIAL METRICS | I22: OPERATIONS METRICS
B23: Metric | C23: YTD Actual | E23: YTD Plan | F23: Variance | G23: Status | I23: Metric | J23: YTD Actual | L23: Plan | M23: Variance | N23: Status
B24: Total Revenue | C24: {=Portfolio_Summary!B6} -> 0 | E24: {=Portfolio_Summary!C6} -> 52500000 | F24: {=Portfolio_Summary!E6} -> -1 | G24: {=Portfolio_Summary!F6} -> ✗ | I24: Occupancy % | J24: {=Portfolio_Summary!B15} -> 0.95219124 | L24: {=Portfolio_Summary!C15} -> 0.94 | M24: {=Portfolio_Summary!E15} -> 0.012969399 | N24: {=Portfolio_Summary!F15} -> ✓
B25: Net Operating Income | C25: {=Portfolio_Summary!B7} -> 7715000 | E25: {=Portfolio_Summary!C7} -> 32000000 | F25: {=Portfolio_Summary!E7} -> -0.75890625 | G25: {=Portfolio_Summary!F7} -> ✗ | I25: Avg NER | J25: {=Portfolio_Summary!B16} -> 1814.3724 | L25: {=Portfolio_Summary!C16} -> 1780 | M25: {=Portfolio_Summary!E16} -> 0.019310329 | N25: {=Portfolio_Summary!F16} -> ✓
B26: NOI Margin % | C26: {=Portfolio_Summary!B8} -> 0 | E26: {=Portfolio_Summary!C8} -> 0.61 | F26: {=Portfolio_Summary!E8} -> -1 | G26: {=Portfolio_Summary!F8} -> ✗ | I26: Lead→Lease Conv | J26: {=Portfolio_Summary!B17} -> 0.090356212 | L26: {=Portfolio_Summary!C17} -> 0.08 | M26: {=Portfolio_Summary!E17} -> 0.12945265 | N26: {=Portfolio_Summary!F17} -> ✓
B27: FFO | C27: {=Portfolio_Summary!B9} -> 100000 | E27: {=Portfolio_Summary!C9} -> 28000000 | F27: {=Portfolio_Summary!E9} -> -0.99642857 | G27: {=Portfolio_Summary!F9} -> ✗ | I27: Renewal Rate | J27: {=Portfolio_Summary!B18} -> 0.72727273 | L27: {=Portfolio_Summary!C18} -> 0.7 | M27: {=Portfolio_Summary!E18} -> 0.038961039 | N27: {=Portfolio_Summary!F18} -> ✓
B28: Same-Store Growth | C28: {=Portfolio_Summary!B10} -> 0.035689774 | E28: {=Portfolio_Summary!C10} -> 0.025 | F28: {=Portfolio_Summary!E10} -> 0.42759094 | G28: {=Portfolio_Summary!F10} -> ✓ | I28: Retention Rate | J28: {=Portfolio_Summary!B19} -> 0.69583333 | L28: {=Portfolio_Summary!C19} -> 0.68 | M28: {=Portfolio_Summary!E19} -> 0.023284314 | N28: {=Portfolio_Summary!F19} -> ✓
B29: DSCR | C29: {=Portfolio_Summary!B11} -> 2.85 | E29: {=Portfolio_Summary!C11} -> 1.4 | F29: {=Portfolio_Summary!E11} -> 1.0357143 | G29: {=Portfolio_Summary!F11} -> ✓ | I29: WO Completion (hrs) | J29: {=Portfolio_Summary!B20} -> 19.392509 | L29: {=Portfolio_Summary!C20} -> 24 | M29: {=Portfolio_Summary!E20} -> 0.19197878 | N29: {=Portfolio_Summary!F20} -> ✓
B32: 3. KEY PERFORMANCE CHARTS
B34: 12-Month Net Cash Flow Trend | I34: Occupancy by Floorplan
B35: Month | C35: Cash Flow ($M) | I35: Floorplan | J35: Occupancy
B36: Jan | C36: =FIN_05_Cash_Flow!B27/1000000 -> 2.09425 | I36: Studio | J36: {=OPS_11_Occupancy_Mix!D5} -> 0.95833333
B37: Feb | C37: =FIN_05_Cash_Flow!C27/1000000 -> 2.20855 | I37: 1BR | J37: {=OPS_11_Occupancy_Mix!D6} -> 0.95588235
B38: Mar | C38: =FIN_05_Cash_Flow!D27/1000000 -> 2.31585 | I38: 1BR+Den | J38: {=OPS_11_Occupancy_Mix!D7} -> 0.9375
B39: Apr | C39: =FIN_05_Cash_Flow!E27/1000000 -> 2.4332 | I39: 2BR | J39: {=OPS_11_Occupancy_Mix!D8} -> 0.93333333
B40: May | C40: =FIN_05_Cash_Flow!F27/1000000 -> 2.5406 | I40: 2BR+Den | J40: {=OPS_11_Occupancy_Mix!D9} -> 0.96428571
B41: Jun | C41: =FIN_05_Cash_Flow!G27/1000000 -> 2.647 | I41: 3BR | J41: {=OPS_11_Occupancy_Mix!D10} -> 0.94444444
B42: Jul | C42: =FIN_05_Cash_Flow!H27/1000000 -> 2.74345 | I42: Penthouse | J42: {=OPS_11_Occupancy_Mix!D11} -> 1
B43: Aug | C43: =FIN_05_Cash_Flow!I27/1000000 -> 2.85595
B44: Sep | C44: =FIN_05_Cash_Flow!J27/1000000 -> 2.97445
B45: Oct | C45: =FIN_05_Cash_Flow!K27/1000000 -> 3.106
B46: Nov | C46: =FIN_05_Cash_Flow!L27/1000000 -> 3.2286
B47: Dec | C47: =FIN_05_Cash_Flow!M27/1000000 -> 3.3522
B50: can y | I50: Marketing Channel Attribution
B51: Stage | C51: Count | I51: Channel | J51: Revenue
B52: Leads | C52: {=MKT_16_Marketing_CPA!C6} -> 1151 | I52: ILS | J52: {=MKT_17_Attribution!E5} -> 425000
B53: Tours | C53: {=MKT_16_Marketing_CPA!E6} -> 401 | I53: Social | J53: {=MKT_17_Attribution!E6} -> 320000
B54: Applications | C54: {=MKT_16_Marketing_CPA!F6} -> 59.850374 | I54: PPC | J54: {=MKT_17_Attribution!E7} -> 285000
B55: Leases | C55: {=MKT_16_Marketing_CPA!G6} -> 104 | I55: Organic | J55: {=MKT_17_Attribution!E8} -> 195000
I56: Referral | J56: {=MKT_17_Attribution!E9} -> 625000
...

Sheet _Executive_Dashboard
B1: PROJECT PATRY - EXECUTIVE DASHBOARD
B2: =TEXT(TODAY(),"mmmm d, yyyy") -> January 12, 2026
B4: FINANCIAL
B6: FFO | D6: NOI | F6: Total Revenue | H6: Cash Position | J6: DSCR | L6: AR Balance
B7: =_xlfn.IFERROR(FIN_01_Investor_Pack!L7,"—") -> 0.0071428571 | D7: =_xlfn.IFERROR(FIN_01_Investor_Pack!L10,"—") -> 0.02117061 | F7: =_xlfn.IFERROR(CAP_21_Investor_Quarterly!B5,"—") -> 13350000 | H7: =_xlfn.IFERROR(FIN_05_Cash_Flow!Q8,"—") -> 3852200 | J7: =_xlfn.IFERROR(FIN_07_Debt_Covenant!D5,"—") -> 1.52 | L7: =_xlfn.IFERROR(FIN_08_AR_Bad_Debt!I4,"—") -> 206500
B10: OPERATIONS
B12: Occupancy | D12: Avg NER | F12: Renewal Rate | H12: Avg Turnover Days | J12: Open Work Orders | L12: Resident NPS
B13: =_xlfn.IFERROR(OPS_11_Occupancy_Mix!D12,"—") -> 0.95219124 | D13: =_xlfn.IFERROR(OPS_11_Occupancy_Mix!G12,"—") -> 1814.3724 | F13: =_xlfn.IFERROR(OPS_12_Renewal_Retention!H13,"—") -> 0.69583333 | H13: =_xlfn.IFERROR(OPS_13_Turnover_MakeReady!K5,"—") -> 0.075697211 | J13: =_xlfn.IFERROR(OPS_14_Maintenance_WO!J4,"—") -> 64 | L13: =_xlfn.IFERROR(OPS_15_Resident_NPS!I4,"—") -> 0.4789916
B16: MARKETING
B18: Total Spend | D18: Total Leads | F18: Avg CPA | H18: New Leases | J18: Attributed Revenue | L18: Avg ROAS
B19: =_xlfn.IFERROR(MKT_16_Marketing_CPA!B16,"—") -> 800 | D19: =_xlfn.IFERROR(MKT_16_Marketing_CPA!C16,"—") -> 42 | F19: =_xlfn.IFERROR(MKT_16_Marketing_CPA!H16,"—") -> 266.66667 | H19: =_xlfn.IFERROR(MKT_16_Marketing_CPA!G16,"—") -> 3 | J19: =_xlfn.IFERROR(MKT_17_Attribution!E12,"—") -> 2060000 | L19: =_xlfn.IFERROR(MKT_17_Attribution!F12,"—") -> 85.833333
B22: DEVELOPMENT
B24: Total Budget | D24: Spent to Date | F24: Est. to Complete | H24: Total Dev Units | J24: Total EV | L24: Active Permits
B25: =_xlfn.IFERROR(DEV_19_Cost_Complete!B10,"—") -> 159000000 | D25: =_xlfn.IFERROR(DEV_19_Cost_Complete!C10,"—") -> 109100000 | F25: =_xlfn.IFERROR(DEV_19_Cost_Complete!E10,"—") -> 25800000 | H25: =_xlfn.IFERROR(DEV_18_Project_EV!B8,"—") -> 550 | J25: =_xlfn.IFERROR(DEV_18_Project_EV!F8,"—") -> 1.9620914e+08 | L25: =_xlfn.IFERROR(COUNTIF(DEV_20_Entitlement_Risk!C5:C10,"<>Approved"),"—") -> 3
B28: CAPITAL MARKETS | H28: ESG & SUSTAINABILITY
B30: Revenue QoQ | D30: NOI Margin | F30: FFO/Share | H30: Energy (kWh/sqft) | J30: Waste Diversion | L30: ENERGY STAR
B31: =_xlfn.IFERROR(CAP_21_Investor_Quarterly!D5,"—") -> 0.019083969 | D31: =_xlfn.IFERROR(CAP_21_Investor_Quarterly!B7,"—") -> 0.614 | F31: =_xlfn.IFERROR(CAP_21_Investor_Quarterly!B11,"—") -> 0.14 | H31: =_xlfn.IFERROR(ESG_22_Sustainability!B5,"—") -> 12.8 | J31: =_xlfn.IFERROR(ESG_22_Sustainability!B7,"—") -> 0.42 | L31: =_xlfn.IFERROR(ESG_22_Sustainability!B9,"—") -> 72
B34: TREND INDICATORS (12-MONTH)
B36: Net Cash Flow | E36: Retention Rate | H36: Occupancy Trend | K36: Revenue Trend
B39: Generated: | C39: =TEXT(NOW(),"mmm d, yyyy h:mm AM/PM") -> Jan 12, 2026 9:41 AM | K39: Project Patry Enterprise Reporting System
B41: ALERTS & STATUS
B43: Covenant Status: | D43: =_xlfn.IFERROR(IF(COUNTIF(FIN_07_Debt_Covenant!F5:F11,"✓ PASS")=7,"✓ ALL COVENANTS PASS","⚠ COVENANT BREACH"),"—") -> ✓ ALL COVENANTS PASS | H43: AR Delinquency: | J43: =_xlfn.IFERROR(FIN_08_AR_Bad_Debt!I7,"—") -> 0.39467312 | L43: High Risk Permits: | M43: =_xlfn.IFERROR(COUNTIF(DEV_20_Entitlement_Risk!G5:G10,"High"),"—") -> 1
B44: Cash Runway: | D44: =_xlfn.IFERROR(FIN_05_Cash_Flow!Q11&" months","—") -> 14.801657785672 months | H44: ESG Behind Target: | J44: =_xlfn.IFERROR(COUNTIF(ESG_22_Sustainability!F5:F12,"⚠ Behind")&"/8","—") -> 8/8

Sheet Variance_Summary
B1: VARIANCE SUMMARY - ALL REPORTS
B2: =TEXT(TODAY(),"As of mmmm d, yyyy")&" | Favorable/Unfavorable Analysis with Executive Commentary" -> A0 o0 January 12, 2026 | Favorable/Unfavorable Analysis with Executive Commentary
B4: Report | C4: Key Metric | D4: Actual | E4: Plan/Target | F4: Variance | G4: Var % | H4: Status | I4: Executive Commentary
B6: FINANCIAL REPORTS
B7: FIN_01_Investor_Pack | C7: FFO (Q4) | D7: =_xlfn.IFERROR(FIN_01_Investor_Pack!E34,"") -> 100000 | F7: =_xlfn.IFERROR(D7-E7,0) -> 100000 | G7: =_xlfn.IFERROR(IF(E7=0,0,(D7-E7)/E7),0) -> 0 | H7: =_xlfn.IFERROR(IF(G7>=0,"✓ Fav","✗ Unfav"),"—") -> ✓ Fav | I7: [Commentary: Enter FFO performance drivers and outlook]
B8: FIN_02_NOI_Pack | C8: Portfolio NOI | D8: =_xlfn.IFERROR(FIN_01_Investor_Pack!E21,"") -> 7715000 | F8: =_xlfn.IFERROR(D8-E8,0) -> 7715000 | G8: =_xlfn.IFERROR(IF(E8=0,0,(D8-E8)/E8),0) -> 0 | H8: =_xlfn.IFERROR(IF(G8>=0,"✓ Fav","✗ Unfav"),"—") -> ✓ Fav | I8: [Commentary: Enter NOI margin drivers and cost control measures]
B9: FIN_03_Rent_Roll | C9: Total Units | D9: =_xlfn.IFERROR(FIN_03_Rent_Roll!G6,"") -> 251 | F9: =_xlfn.IFERROR(D9-E9,0) -> 251 | G9: =_xlfn.IFERROR(IF(E9=0,0,(D9-E9)/E9),0) -> 0 | H9: =_xlfn.IFERROR(IF(G9>=0,"✓ Fav","✗ Unfav"),"—") -> ✓ Fav | I9: [Commentary: Enter rent roll changes and lease expiration status]
B10: FIN_04_Budget_Variance | C10: Total Variance | F10: =_xlfn.IFERROR(D10-E10,0) -> 0 | I10: [Commentary: GL-level variance analysis pending data population]
B11: FIN_05_Cash_Flow | C11: Cash Position | D11: =_xlfn.IFERROR(FIN_05_Cash_Flow!Q8,"") -> 3852200 | F11: =_xlfn.IFERROR(D11-E11,0) -> 3852200 | G11: =_xlfn.IFERROR(IF(E11=0,0,(D11-E11)/E11),0) -> 0 | H11: =_xlfn.IFERROR(IF(G11>=0,"✓ Fav","✗ Unfav"),"—") -> ✓ Fav | I11: [Commentary: Enter liquidity position and runway analysis]
B12: FIN_06_Capex | C12: % Budget Spent | D12: =_xlfn.IFERROR(FIN_06_Capex!I22,"") -> 395000 | F12: =_xlfn.IFERROR(D12-E12,0) -> 395000 | G12: =_xlfn.IFERROR(IF(E12=0,0,(E12-D12)/E12),0) -> 0 | H12: =_xlfn.IFERROR(IF(G12>=0,"✓ Fav","✗ Unfav"),"—") -> ✓ Fav | I12: [Commentary: Enter capex project status and timing]
B13: FIN_07_Debt_Covenant | C13: DSCR | D13: =_xlfn.IFERROR(FIN_07_Debt_Covenant!D5,"") -> 1.52 | E13: =_xlfn.IFERROR(FIN_07_Debt_Covenant!C5,"") -> 1.25 | F13: =_xlfn.IFERROR(D13-E13,0) -> 0.27 | G13: =_xlfn.IFERROR(IF(E13=0,0,(D13-E13)/E13),0) -> 0.216 | H13: =_xlfn.IFERROR(IF(D13>=E13,"✓ Pass","✗ Breach"),"—") -> ✓ Pass | I13: [Commentary: Enter covenant headroom and debt strategy]
B14: FIN_08_AR_Bad_Debt | C14: Delinquency Rate | D14: =_xlfn.IFERROR(FIN_08_AR_Bad_Debt!I7,"") -> 0.39467312 | F14: =_xlfn.IFERROR(D14-E14,0) -> 0.39467312 | G14: =_xlfn.IFERROR(IF(E14=0,0,(E14-D14)/E14),0) -> 0 | H14: =_xlfn.IFERROR(IF(D14<=E14,"✓ Fav","⚠ Alert"),"—") -> ⚠ Alert | I14: [Commentary: Enter collections strategy and aged AR actions]
B16: OPERATIONS REPORTS
B17: OPS_09_Leasing_OnePager | C17: MTD Leases | D17: =_xlfn.IFERROR(OPS_09_Leasing_OnePager!D10,0) -> 0 | F17: =_xlfn.IFERROR(D17-E17,0) -> 0 | G17: =_xlfn.IFERROR(IF(E17=0,0,(D17-E17)/E17),0) -> 0 | H17: =_xlfn.IFERROR(IF(G17>=0,"✓ Fav","✗ Unfav"),"—") -> ✓ Fav | I17: [Commentary: Enter leasing velocity and pipeline status]
B18: OPS_10_Leasing_Funnel | C18: Lead→Lease Conv | D18: =_xlfn.IFERROR(OPS_10_Leasing_Funnel!I12,0) -> 0.090356212 | F18: =_xlfn.IFERROR(D18-E18,0) -> 0.090356212 | G18: =_xlfn.IFERROR(IF(E18=0,0,(D18-E18)/E18),0) -> 0 | H18: =_xlfn.IFERROR(IF(G18>=0,"✓ Fav","✗ Unfav"),"—") -> ✓ Fav | I18: [Commentary: Enter conversion bottlenecks and improvements]
B19: OPS_11_Occupancy_Mix | C19: Portfolio Occupancy | D19: =_xlfn.IFERROR(OPS_11_Occupancy_Mix!D12,0) -> 0.95219124 | F19: =_xlfn.IFERROR(D19-E19,0) -> 0.95219124 | G19: =_xlfn.IFERROR(IF(E19=0,0,(D19-E19)/E19),0) -> 0 | H19: =_xlfn.IFERROR(IF(G19>=0,"✓ Fav","✗ Unfav"),"—") -> ✓ Fav | I19: [Commentary: Enter unit type performance and absorption]
B20: OPS_12_Renewal_Retention | C20: Renewal Rate | D20: =_xlfn.IFERROR(OPS_12_Renewal_Retention!D10,0) -> 0.72727273 | F20: =_xlfn.IFERROR(D20-E20,0) -> 0.72727273 | G20: =_xlfn.IFERROR(IF(E20=0,0,(D20-E20)/E20),0) -> 0 | H20: =_xlfn.IFERROR(IF(G20>=0,"✓ Fav","✗ Unfav"),"—") -> ✓ Fav | I20: [Commentary: Enter renewal trends and concession strategy]
B21: OPS_13_Turnover_MakeReady | C21: Avg Turnover Days | D21: =_xlfn.IFERROR(OPS_13_Turnover_MakeReady!K5,0) -> 0.075697211 | F21: =_xlfn.IFERROR(D21-E21,0) -> 0.075697211 | G21: =_xlfn.IFERROR(IF(E21=0,0,(E21-D21)/E21),0) -> 0 | H21: =_xlfn.IFERROR(IF(D21<=E21,"✓ Fav","✗ Unfav"),"—") -> ✗ Unfav | I21: [Commentary: Enter make-ready efficiency and cost drivers]
B22: OPS_14_Maintenance_WO | C22: Avg WO Completion (hrs) | D22: =_xlfn.IFERROR(OPS_14_Maintenance_WO!E11,0) -> 19.392509 | F22: =_xlfn.IFERROR(D22-E22,0) -> 19.392509 | G22: =_xlfn.IFERROR(IF(E22=0,0,(E22-D22)/E22),0) -> 0 | H22: =_xlfn.IFERROR(IF(D22<=E22,"✓ Fav","✗ Unfav"),"—") -> ✗ Unfav | I22: [Commentary: Enter maintenance staffing and SLA performance]
B23: OPS_15_Resident_NPS | C23: Overall NPS | D23: =_xlfn.IFERROR(OPS_15_Resident_NPS!I4,0) -> 0.4789916 | F23: =_xlfn.IFERROR(D23-E23,0) -> 0.4789916 | G23: =_xlfn.IFERROR(IF(E23=0,0,(D23-E23)/E23),0) -> 0 | H23: =_xlfn.IFERROR(IF(D23>=E23,"✓ Fav","✗ Unfav"),"—") -> ✓ Fav | I23: [Commentary: Enter resident satisfaction drivers and detractors]
B25: MARKETING REPORTS
B26: MKT_16_Marketing_CPA | C26: Blended CPA | D26: =_xlfn.IFERROR(MKT_16_Marketing_CPA!H6,0) -> 230.76923 | F26: =_xlfn.IFERROR(D26-E26,0) -> 230.76923 | G26: =_xlfn.IFERROR(IF(E26=0,0,(E26-D26)/E26),0) -> 0 | H26: =_xlfn.IFERROR(IF(D26<=E26,"✓ Fav","✗ Unfav"),"—") -> ✗ Unfav | I26: [Commentary: Enter channel efficiency and spend optimization]
B27: MKT_17_Attribution | C27: Avg ROAS | D27: =_xlfn.IFERROR(MKT_17_Attribution!F12,0) -> 85.833333 | F27: =_xlfn.IFERROR(D27-E27,0) -> 85.833333 | G27: =_xlfn.IFERROR(IF(E27=0,0,(D27-E27)/E27),0) -> 0 | H27: =_xlfn.IFERROR(IF(D27>=E27,"✓ Fav","✗ Unfav"),"—") -> ✓ Fav | I27: [Commentary: Enter attribution model insights and channel mix]
B29: DEVELOPMENT REPORTS
B30: DEV_18_Project_EV | C30: Portfolio EV | D30: =_xlfn.IFERROR(DEV_18_Project_EV!F8,0) -> 1.9620914e+08 | F30: =_xlfn.IFERROR(D30-E30,0) -> 1.9620914e+08 | G30: =_xlfn.IFERROR(IF(E30=0,0,(D30-E30)/E30),0) -> 0 | H30: =_xlfn.IFERROR(IF(G30>=0,"✓ Fav","✗ Unfav"),"—") -> ✓ Fav | I30: [Commentary: Enter valuation drivers and cap rate assumptions]
B31: DEV_19_Cost_Complete | C31: Budget Variance | D31: =_xlfn.IFERROR(DEV_19_Cost_Complete!G10,0) -> 0 | F31: =_xlfn.IFERROR(D31-E31,0) -> 0 | H31: =_xlfn.IFERROR(IF(D31>=0,"✓ On Track","⚠ Over"),"—") -> ✓ On Track | I31: [Commentary: Enter cost drivers and contingency status]
B32: DEV_20_Entitlement_Risk | C32: High Risk Permits | D32: =_xlfn.IFERROR(COUNTIF(DEV_20_Entitlement_Risk!G5:G10,"High"),0) -> 1 | F32: =_xlfn.IFERROR(D32-E32,0) -> 1 | H32: =_xlfn.IFERROR(IF(D32=0,"✓ Clear","⚠ Risk"),"—") -> ⚠ Risk | I32: [Commentary: Enter permit status and mitigation actions]
B34: CAPITAL MARKETS REPORTS
B35: CAP_21_Investor_Quarterly | C35: FFO Growth YoY | D35: =_xlfn.IFERROR(CAP_21_Investor_Quarterly!F10,0) -> 0.060150376 | F35: =_xlfn.IFERROR(D35-E35,0) -> 0.060150376 | G35: =_xlfn.IFERROR(IF(E35=0,0,(D35-E35)/E35),0) -> 0 | H35: =_xlfn.IFERROR(IF(D35>=E35,"✓ Fav","✗ Unfav"),"—") -> ✓ Fav | I35: [Commentary: Enter investor messaging and distribution guidance]
B37: ESG REPORTS
B38: ESG_22_Sustainability | C38: Metrics On Track | D38: =_xlfn.IFERROR(COUNTIF(ESG_22_Sustainability!F5:F12,"✓ On Track"),0) -> 0 | F38: =_xlfn.IFERROR(D38-E38,0) -> 0 | G38: =_xlfn.IFERROR(IF(E38=0,0,(D38-E38)/E38),0) -> 0 | H38: =_xlfn.IFERROR(IF(D38>=6,"✓ Fav","⚠ Behind"),"—") -> ⚠ Behind | I38: [Commentary: Enter sustainability initiatives and progress]
B40: VARIANCE SUMMARY DASHBOARD
B42: Total Reports: | E42: =_xlfn.IFERROR(COUNTIF(H7:H14,"✓*")+COUNTIF(H17:H23,"✓*")+COUNTIF(H26:H27,"✓*")+COUNTIF(H30:H32,"✓*")+COUNTIF(H35,"✓*")+COUNTIF(H38,"✓*"),"—") -> 15 | G42: =_xlfn.IFERROR(COUNTIF(H7:H14,"✗*")+COUNTIF(H17:H23,"✗*")+COUNTIF(H26:H27,"✗*")+COUNTIF(H30:H32,"✗*")+COUNTIF(H35,"✗*")+COUNTIF(H38,"✗*"),"—") -> 3 | I42: =_xlfn.IFERROR(COUNTIF(H7:H38,"⚠*"),"—") -> 3
B44: OVERALL STATUS: | C44: =_xlfn.IFERROR(IF(G42<=3,"✓ ON TRACK",IF(G42<=5,"⚠ WATCH","✗ ACTION NEEDED")),"—") -> ✓ ON TRACK
B46: COMMENTARY GUIDELINES
B47: • Favorable variances: Explain drivers, sustainability, and outlook
B48: • Unfavorable variances: Root cause, corrective actions, timeline to resolution
B49: • Alerts/Risks: Mitigation strategy, escalation status, resource requirements
B50: • Use specific numbers and dates; avoid vague language
B51: • Reference related reports for cross-functional impacts
...

Sheet Forecast_Reconciliation
A1: FORECAST RECONCILIATION & BRIDGE ANALYSIS
A2: Tracking Budget → Reforecast → Actual with Variance Explanations | Period: January 2026
A4: FORECAST BRIDGE SUMMARY
A6: Original Budget | B6: 585000 | C6: RF1 Adjustment | D6: 15000 | E6: RF2 Adjustment | F6: 8000 | G6: Current Forecast | H6: =B6+D6+F6 -> 608000 | I6: Actual | J6: 621000 | K6: Variance | L6: =J6-H6 -> 13000
A9: RECONCILIATION BY COST CENTER
A10: Cost Center | B10: Orig Budget | C10: RF1 (Q1) | D10: RF1 Δ | E10: RF2 (Q2) | F10: RF2 Δ | G10: Curr Fcst | H10: Actual | I10: Var to CF | J10: Var % | K10: Status | L10: Variance Explanation
A11: REVENUE
A12: 4100 Rental Revenue | B12: 1100000 | C12: 1115000 | D12: =C12-B12 -> 15000 | E12: 1120000 | F12: =E12-C12 -> 5000 | G12: {=E12} -> 1120000 | H12: 1125000 | I12: =H12-G12 -> 5000 | J12: =IF(G12=0,0,(H12-G12)/ABS(G12)) -> 0.0044642857 | K12: =IF(ABS(J12)<=0.03,"✓",IF(ABS(J12)<=0.07,"⚠","✗")) -> ✓ | L12: Occupancy 95.2% vs 94% plan; faster lease-up at Parkside
A13: 4200 Other Income | B13: 50000 | C13: 48000 | D13: =C13-B13 -> -2000 | E13: 46000 | F13: =E13-C13 -> -2000 | G13: {=E13} -> 46000 | H13: 45000 | I13: =H13-G13 -> -1000 | J13: =IF(G13=0,0,(H13-G13)/ABS(G13)) -> -0.02173913 | K13: =IF(ABS(J13)<=0.03,"✓",IF(ABS(J13)<=0.07,"⚠","✗")) -> ✓ | L13: Parking revenue below target; pet fees on track
A14: 4300 Concessions | B14: -35000 | C14: -32000 | D14: =C14-B14 -> 3000 | E14: -30000 | F14: =E14-C14 -> 2000 | G14: {=E14} -> -30000 | H14: -28000 | I14: =H14-G14 -> 2000 | J14: =IF(G14=0,0,(H14-G14)/ABS(G14)) -> 0.066666667 | K14: =IF(ABS(J14)<=0.03,"✓",IF(ABS(J14)<=0.07,"⚠","✗")) -> ⚠ | L14: Strong demand reduced need for concessions
A15: Revenue Subtotal | B15: =SUM(B12:B14) -> 1115000 | C15: =SUM(C12:C14) -> 1131000 | D15: =C15-B15 -> 16000 | E15: =SUM(E12:E14) -> 1136000 | F15: =E15-C15 -> 5000 | G15: =SUM(G12:G14) -> 1136000 | H15: =SUM(H12:H14) -> 1142000 | I15: =H15-G15 -> 6000 | J15: =IF(G15=0,0,(H15-G15)/ABS(G15)) -> 0.0052816901 | K15: 0 | L15: 0
A17: EXPENSES
A18: 5100 Payroll & Benefits | B18: -180000 | C18: -182000 | D18: =C18-B18 -> -2000 | E18: -184000 | F18: =E18-C18 -> -2000 | G18: {=E18} -> -184000 | H18: -185000 | I18: =H18-G18 -> -1000 | J18: =IF(G18=0,0,(H18-G18)/ABS(G18)) -> -0.0054347826 | K18: =IF(ABS(J18)<=0.03,"✓",IF(ABS(J18)<=0.07,"⚠","✗")) -> ✓ | L18: OT for maint backlog; hiring tech Feb to normalize
A19: 5200 Repairs & Maint | B19: -70000 | C19: -68000 | D19: =C19-B19 -> 2000 | E19: -65000 | F19: =E19-C19 -> 3000 | G19: {=E19} -> -65000 | H19: -62000 | I19: =H19-G19 -> 3000 | J19: =IF(G19=0,0,(H19-G19)/ABS(G19)) -> 0.046153846 | K19: =IF(ABS(J19)<=0.03,"✓",IF(ABS(J19)<=0.07,"⚠","✗")) -> ⚠ | L19: Preventive program reducing reactive repairs
A20: 5300 Utilities | B20: -55000 | C20: -52000 | D20: =C20-B20 -> 3000 | E20: -50000 | F20: =E20-C20 -> 2000 | G20: {=E20} -> -50000 | H20: -48000 | I20: =H20-G20 -> 2000 | J20: =IF(G20=0,0,(H20-G20)/ABS(G20)) -> 0.04 | K20: =IF(ABS(J20)<=0.03,"✓",IF(ABS(J20)<=0.07,"⚠","✗")) -> ⚠ | L20: LED retrofit savings; mild weather
A21: 5400 Insurance | B21: -30000 | C21: -31000 | D21: =C21-B21 -> -1000 | E21: -32000 | F21: =E21-C21 -> -1000 | G21: {=E21} -> -32000 | H21: -32000 | I21: =H21-G21 -> 0 | J21: =IF(G21=0,0,(H21-G21)/ABS(G21)) -> 0 | K21: =IF(ABS(J21)<=0.03,"✓",IF(ABS(J21)<=0.07,"⚠","✗")) -> ✓ | L21: Premium increase at renewal; shopping alternatives
A22: 5500 Property Taxes | B22: -85000 | C22: -85000 | D22: =C22-B22 -> 0 | E22: -85000 | F22: =E22-C22 -> 0 | G22: {=E22} -> -85000 | H22: -85000 | I22: =H22-G22 -> 0 | J22: =IF(G22=0,0,(H22-G22)/ABS(G22)) -> 0 | K22: =IF(ABS(J22)<=0.03,"✓",IF(ABS(J22)<=0.07,"⚠","✗")) -> ✓ | L22: On budget; appeal filed for 2027
A23: 5600 Marketing | B23: -28000 | C23: -26000 | D23: =C23-B23 -> 2000 | E23: -25000 | F23: =E23-C23 -> 1000 | G23: {=E23} -> -25000 | H23: -24000 | I23: =H23-G23 -> 1000 | J23: =IF(G23=0,0,(H23-G23)/ABS(G23)) -> 0.04 | K23: =IF(ABS(J23)<=0.03,"✓",IF(ABS(J23)<=0.07,"⚠","✗")) -> ⚠ | L23: Shifted to digital; higher ROI channels
A24: 5700 Professional Fees | B24: -15000 | C24: -16000 | D24: =C24-B24 -> -1000 | E24: -17000 | F24: =E24-C24 -> -1000 | G24: {=E24} -> -17000 | H24: -18000 | I24: =H24-G24 -> -1000 | J24: =IF(G24=0,0,(H24-G24)/ABS(G24)) -> -0.058823529 | K24: =IF(ABS(J24)<=0.03,"✓",IF(ABS(J24)<=0.07,"⚠","✗")) -> ⚠ | L24: Legal fees for lease dispute (one-time)
A25: 5800 Admin & General | B25: -25000 | C25: -24000 | D25: =C25-B25 -> 1000 | E25: -23000 | F25: =E25-C25 -> 1000 | G25: {=E25} -> -23000 | H25: -22000 | I25: =H25-G25 -> 1000 | J25: =IF(G25=0,0,(H25-G25)/ABS(G25)) -> 0.043478261 | K25: =IF(ABS(J25)<=0.03,"✓",IF(ABS(J25)<=0.07,"⚠","✗")) -> ⚠ | L25: Cost control initiatives effective
A26: 5900 Contract Services | B26: -42000 | C26: -43000 | D26: =C26-B26 -> -1000 | E26: -44000 | F26: =E26-C26 -> -1000 | G26: {=E26} -> -44000 | H26: -45000 | I26: =H26-G26 -> -1000 | J26: =IF(G26=0,0,(H26-G26)/ABS(G26)) -> -0.022727273 | K26: =IF(ABS(J26)<=0.03,"✓",IF(ABS(J26)<=0.07,"⚠","✗")) -> ✓ | L26: Landscaping scope expansion; renegotiating Q2
A27: Expense Subtotal | B27: =SUM(B18:B26) -> -530000 | C27: =SUM(C18:C26) -> -527000 | D27: =C27-B27 -> 3000 | E27: =SUM(E18:E26) -> -525000 | F27: =E27-C27 -> 2000 | G27: =SUM(G18:G26) -> -525000 | H27: =SUM(H18:H26) -> -521000 | I27: =H27-G27 -> 4000 | J27: =IF(G27=0,0,(H27-G27)/ABS(G27)) -> 0.0076190476
A29: NET OPERATING INCOME | B29: =B15+B27 -> 585000 | C29: =C15+C27 -> 604000 | D29: =C29-B29 -> 19000 | E29: =E15+E27 -> 611000 | F29: =E29-C29 -> 7000 | G29: =G15+G27 -> 611000 | H29: =H15+H27 -> 621000 | I29: =H29-G29 -> 10000 | J29: =IF(G29=0,0,(H29-G29)/ABS(G29)) -> 0.016366612 | K29: =IF(J29>=0,"✓",IF(J29>=-0.05,"⚠","✗")) -> ✓
A31: MONTHLY FORECAST HISTORY
A32: Period | B32: Orig Budget | C32: RF1 | D32: RF1 Chg | E32: RF2 | F32: RF2 Chg | G32: Curr Fcst | H32: Actual | I32: Variance | J32: Var % | K32: Fcst Acc | L32: Commentary
A33: Jan-26 | B33: 585000 | C33: 600000 | D33: =C33-B33 -> 15000 | E33: 608000 | F33: =E33-C33 -> 8000 | G33: {=E33} -> 608000 | H33: 621000 | I33: =H33-G33 -> 13000 | J33: =IF(G33=0,0,(H33-G33)/G33) -> 0.021381579 | K33: =1-ABS(J33) -> 0.97861842 | L33: Strong start; beat all forecasts
A34: Feb-26 | B34: 590000 | C34: 605000 | D34: =C34-B34 -> 15000 | E34: 612000 | F34: =E34-C34 -> 7000 | G34: {=E34} -> 612000 | H34: — | I34: — | J34: — | K34: — | L34: [Pending]
A35: Mar-26 | B35: 605000 | C35: 618000 | D35: =C35-B35 -> 13000 | E35: 625000 | F35: =E35-C35 -> 7000 | G35: {=E35} -> 625000 | H35: — | I35: — | J35: — | K35: — | L35: [Pending]
A36: Q1 Total | B36: 1780000 | C36: 1823000 | D36: =C36-B36 -> 43000 | E36: 1845000 | F36: =E36-C36 -> 22000 | G36: {=E36} -> 1845000 | H36: — | I36: — | J36: — | K36: — | L36: Q1 forecast tracking ahead
A38: REFORECAST CHANGE LOG
A39: RF # | B39: Date | C39: Impact | D39: Category | F39: Description of Change | K39: Approved By | L39: Status
A40: RF1 | B40: 2026-01-15 | C40: 23000 | D40: Revenue | F40: Increased rental revenue forecast based on Jan occupancy trends (+$15K) and reduced concessions (+$8K) | K40: CFO | L40: ✓ Approved
A41: RF1 | B41: 2026-01-15 | C41: -8000 | D41: Expense | F41: Added payroll for OT (-$2K), increased insurance reserve (-$1K), added legal contingency (-$5K) | K41: CFO | L41: ✓ Approved
A42: RF2 | B42: 2026-02-01 | C42: 14000 | D42: Revenue | F42: Further rental income increase based on Feb pipeline (+$5K), parking adjustment (-$2K), concessions (+$2K) | K42: CFO | L42: ✓ Approved
A43: RF2 | B43: 2026-02-01 | C43: -6000 | D43: Expense | F43: Payroll adjustment (-$2K), insurance finalized (-$1K), legal update (-$1K), contracts (-$1K), offset by savings (+$-1K) | K43: CFO | L43: ✓ Approved
A44: RF3 | B44: 2026-02-15 | C44: 0 | D44: TBD | F44: [Next reforecast scheduled for Feb 15 - will incorporate Jan actuals] | K44: Pending | L44: ⏳ Scheduled
A46: Forecast Accuracy Target: 97% | Current: 97.9% | F46: Last Updated: | G46: =TEXT(NOW(),"mmmm d, yyyy") -> January 12, 2026 | J46: Next RF: | K46: Feb 15, 2026

Sheet Variance_Root_Cause
B1: VARIANCE ROOT CAUSE ANALYSIS
B2: Drill-Down Analysis: Monthly Totals → Cost Centers → Transactions | January 2026
B4: LEVEL 1: TOTAL VARIANCE SUMMARY
B6: Total Variance: | C6: 36000 | E6: Favorable: | F6: 57000 | G6: Unfavorable: | H6: -21000 | I6: Net: | J6: =_xlfn.IFERROR(F6+H6,0) -> 36000
B10: LEVEL 2: CATEGORY BREAKDOWN
B11: Category | C11: Actual | D11: Budget | E11: Variance | F11: Var % | G11: % of Total | H11: Driver | I11: Status | J11: Root Cause Summary
B12: ▼ REVENUE | C12: 425000 | D12: 400000 | E12: =_xlfn.IFERROR(C12-D12,0) -> 25000 | F12: =_xlfn.IFERROR(E12/D12,0) -> 0.0625 | G12: =_xlfn.IFERROR(E12/$E$7,0) -> 0 | H12: Multiple | I12: ✓ | J12: Strong rental income; parking outperformance
B13: Rental Income | C13: 380000 | D13: 365000 | E13: =_xlfn.IFERROR(C13-D13,0) -> 15000 | F13: =_xlfn.IFERROR(E13/D13,0) -> 0.04109589 | G13: =_xlfn.IFERROR(E13/$E$7,0) -> 0 | H13: Rate | I13: ✓ | J13: Higher achieved rents vs budget
B14: Parking Revenue | C14: 28000 | D14: 22000 | E14: =_xlfn.IFERROR(C14-D14,0) -> 6000 | F14: =_xlfn.IFERROR(E14/D14,0) -> 0.27272727 | G14: =_xlfn.IFERROR(E14/$E$7,0) -> 0 | H14: Volume | I14: ✓ | J14: New parking tier pricing effective
B15: Other Income | C15: 17000 | D15: 13000 | E15: =_xlfn.IFERROR(C15-D15,0) -> 4000 | F15: =_xlfn.IFERROR(E15/D15,0) -> 0.30769231 | G15: =_xlfn.IFERROR(E15/$E$7,0) -> 0 | H15: Mix | I15: ✓ | J15: Pet fees and storage rentals up
B16: ▼ EXPENSES | C16: 196000 | D16: 215000 | E16: =_xlfn.IFERROR(C16-D16,0) -> -19000 | F16: =_xlfn.IFERROR(E16/D16,0) -> -0.088372093 | G16: =_xlfn.IFERROR(E16/$E$7,0) -> 0 | H16: Multiple | I16: ✓ | J16: Cost controls effective
B17: Payroll & Benefits | C17: 85000 | D17: 92000 | E17: =_xlfn.IFERROR(C17-D17,0) -> -7000 | F17: =_xlfn.IFERROR(E17/D17,0) -> -0.076086957 | G17: =_xlfn.IFERROR(E17/$E$7,0) -> 0 | H17: Volume | I17: ✓ | J17: Delayed hiring; lower overtime
B18: Repairs & Maintenance | C18: 32000 | D18: 28000 | E18: =_xlfn.IFERROR(C18-D18,0) -> 4000 | F18: =_xlfn.IFERROR(E18/D18,0) -> 0.14285714 | G18: =_xlfn.IFERROR(E18/$E$7,0) -> 0 | H18: Volume | I18: ⚠ | J18: HVAC emergency repairs in Bldg C
B19: Utilities | C19: 24000 | D19: 26000 | E19: =_xlfn.IFERROR(C19-D19,0) -> -2000 | F19: =_xlfn.IFERROR(E19/D19,0) -> -0.076923077 | G19: =_xlfn.IFERROR(E19/$E$7,0) -> 0 | H19: Rate | I19: ✓ | J19: Energy efficiency improvements
B20: Marketing | C20: 18000 | D20: 25000 | E20: =_xlfn.IFERROR(C20-D20,0) -> -7000 | F20: =_xlfn.IFERROR(E20/D20,0) -> -0.28 | G20: =_xlfn.IFERROR(E20/$E$7,0) -> 0 | H20: Timing | I20: ✓ | J20: Campaign shifted to Q2
B21: Admin & G&A | C21: 22000 | D21: 24000 | E21: =_xlfn.IFERROR(C21-D21,0) -> -2000 | F21: =_xlfn.IFERROR(E21/D21,0) -> -0.083333333 | G21: =_xlfn.IFERROR(E21/$E$7,0) -> 0 | H21: Rate | I21: ✓ | J21: Contract renegotiations
B22: Insurance | C22: 15000 | D22: 20000 | E22: =_xlfn.IFERROR(C22-D22,0) -> -5000 | F22: =_xlfn.IFERROR(E22/D22,0) -> -0.25 | G22: =_xlfn.IFERROR(E22/$E$7,0) -> 0 | H22: One-Time | I22: ✓ | J22: Multi-year policy discount
B25: LEVEL 3: COST CENTER DRILL-DOWN (Repairs & Maintenance)
B26: Cost Center | C26: Actual | D26: Budget | H26: Owner | I26: Status | J26: Action Required
B27: Building A - Exterior | C27: 6500 | D27: 7000 | E27: =_xlfn.IFERROR(C27-D27,0) -> -500 | F27: =_xlfn.IFERROR(E27/D27,0) -> -0.071428571 | H27: J. Martinez | I27: ✓ | J27: On track
B28: Building B - Interiors | C28: 5200 | D28: 5500 | E28: =C28-D28 -> -300 | F28: =E28/D28 -> -0.054545455 | G28: Volume | H28: J. Martinez | I28: ✓ | J28: Under budget
B29: Building C - HVAC | C29: 12800 | D29: 6000 | E29: =C29-D29 -> 6800 | F29: =E29/D29 -> 1.1333333 | G29: One-Time | H29: T. Williams | I29: ✗ | J29: Emergency compressor replacement
B30: Building D - Plumbing | C30: 3500 | D30: 4000 | E30: =C30-D30 -> -500 | F30: =E30/D30 -> -0.125 | G30: Rate | H30: J. Martinez | I30: ✓ | J30: Preventive maintenance
B31: Common Areas | C31: 2800 | D31: 3500 | E31: =C31-D31 -> -700 | F31: =E31/D31 -> -0.2 | G31: Volume | H31: S. Chen | I31: ✓ | J31: Deferred to Q2
B32: Landscaping | C32: 1200 | D32: 2000 | E32: =C32-D32 -> -800 | F32: =E32/D32 -> -0.4 | G32: Timing | H32: S. Chen | I32: ✓ | J32: Seasonal savings
B33: TOTAL R&M | C33: =SUM(C27:C32) -> 32000 | D33: =SUM(D27:D32) -> 28000 | E33: =C33-D33 -> 4000 | F33: =E33/D33 -> 0.14285714 | G33: — | H33: — | I33: ⚠ | J33: Net unfavorable due to HVAC
B36: LEVEL 4: TRANSACTION DETAIL (Building C - HVAC Variance: +$6,800)
B37: Date | C37: Vendor | D37: Description | E37: Amount | F37: PO # | G37: GL Code | H37: Approved By | I37: Type | J37: Notes
B38: 01/05/26 | C38: HVAC Solutions Inc | D38: Emergency compressor diagnostic | E38: 850 | F38: PO-2601 | G38: 6200-301 | H38: T. Williams | I38: Service | J38: After-hours call
B39: 01/08/26 | C39: HVAC Solutions Inc | D39: Compressor replacement - parts | E39: 6200 | F39: PO-2605 | G39: 6200-301 | H39: VP Ops | I39: Capital | J39: RTU-C3 unit failure
B40: 01/09/26 | C40: HVAC Solutions Inc | D40: Compressor replacement - labor | E40: 2800 | F40: PO-2605 | G40: 6200-301 | H40: VP Ops | I40: Service | J40: 8-hour install
B41: 01/12/26 | C41: TempControl Services | D41: Temporary cooling rental | E41: 1500 | F41: PO-2608 | G41: 6200-302 | H41: T. Williams | I41: Rental | J41: 3-day rental
B42: 01/15/26 | C42: HVAC Solutions Inc | D42: System testing & calibration | E42: 950 | F42: PO-2612 | G42: 6200-301 | H42: T. Williams | I42: Service | J42: Final commissioning
B43: 01/20/26 | C43: Building Systems Co | D43: Preventive maintenance - other units | E43: 500 | F43: PO-2615 | G43: 6200-301 | H43: J. Martinez | I43: Service | J43: Scheduled PM
D44: TOTAL HVAC SPEND (Jan) | E44: =_xlfn.IFERROR(SUM(E38:E43),0) -> 12800 | J44: Budget: $6,000
B47: DRIVER TYPE LEGEND | F47: ROOT CAUSE ANALYSIS SUMMARY
B48: Volume | C48: Quantity-driven variance (more/fewer units, hours, etc.) | F48: Primary Driver: | G48: One-Time (HVAC failure = 67% of unfavorable)
B49: Rate | C49: Price-driven variance (higher/lower unit cost) | F49: Secondary: | G49: Volume variances in labor & maintenance
B50: Mix | C50: Product/service mix shift affecting margins | F50: Offsetting: | G50: Rate savings from contract renegotiations
B51: Timing | C51: Planned spend shifted to different period | F51: Recommendation: | G51: Increase PM budget for aging equipment
...

Sheet Daily_Leasing_Flash
A1: DAILY LEASING FLASH
A2: Executive Morning Briefing | Updated: 1/11/2026
A4: HEADLINE METRICS
A5: Occupancy | C5: NER | E5: MTD Leases | G5: Lead→Lease
A6: {=OPS_11_Occupancy_Mix!D12} -> 0.95219124 | C6: {=OPS_11_Occupancy_Mix!G12} -> 1814.3724 | E6: {=OPS_10_Leasing_Funnel!E12} -> 104 | G6: {=OPS_10_Leasing_Funnel!I12} -> 0.090356212
A8: LEASING FUNNEL (MTD) | F8: MARKETING PERFORMANCE
A9: Stage | B9: Count | C9: Conversion | D9: vs Target | F9: Metric | G9: Value | H9: Status
A10: Leads | B10: {=OPS_10_Leasing_Funnel!B12} -> 1151 | C10: — | D10: — | F10: Total Spend (MTD) | G10: {=MKT_16_Marketing_CPA!B6} -> 24000 | H10: —
A11: Tours | B11: {=OPS_10_Leasing_Funnel!C12} -> 401 | C11: {=OPS_10_Leasing_Funnel!F12} -> 0.3483927 | D11: =C11-0.35 -> -0.001607298 | F11: Cost Per Lead | G11: {=MKT_16_Marketing_CPA!D6} -> 20.851434 | H11: =IF(G11<=25,"✓ On Track","⚠ High") -> ✓ On Track
A12: Applications | B12: {=OPS_10_Leasing_Funnel!D12} -> 231 | C12: {=OPS_10_Leasing_Funnel!G12} -> 0.57605985 | D12: =C12-0.55 -> 0.02605985 | F12: Cost Per Acquisition | G12: {=MKT_16_Marketing_CPA!H6} -> 230.76923 | H12: =IF(G12<=300,"✓ On Track","⚠ High") -> ✓ On Track
A13: Leases | B13: {=OPS_10_Leasing_Funnel!E12} -> 104 | C13: {=OPS_10_Leasing_Funnel!H12} -> 0.45021645 | D13: =C13-0.45 -> 0.00021645022 | F13: LTV:CAC Ratio | G13: {=MKT_16_Marketing_CPA!B28} -> 311.31353 | H13: =IF(G13>=3,"✓ Healthy","⚠ Low") -> ✓ Healthy
A15: ⚠ ACTION REQUIRED
A16: Priority | B16: Alert | C16: Metric | D16: Value | E16: Threshold | F16: Owner | G16: Due
A17: 🔴 HIGH | B17: Lead Response SLA | C17: Contacts <1hr | D17: 78% | E17: >90% | F17: Leasing Mgr | G17: Today
A18: 🟡 MED | B18: Stale Leads | C18: No contact 48hrs | D18: 23 | E18: <15 | F18: Leasing Team | G18: Tomorrow
A19: 🟡 MED | B19: Expiring Leases | C19: No renewal offer | D19: 12 | E19: 0 | F19: Renewals Coord | G19: This Week
A21: TODAY'S ACTIVITY SNAPSHOT | F21: TOP CHANNELS BY LEASES
A22: Metric | B22: Today | C22: WTD | D22: MTD | F22: Channel | G22: Leases | H22: CPA
A23: New Leads | B23: 18 | C23: 85 | D23: 1151 | F23: Direct/Organic | G23: {=OPS_10_Leasing_Funnel!E9} -> 32 | H23: {=MKT_16_Marketing_CPA!H14} -> 0
A24: Tours Completed | B24: 6 | C24: 32 | D24: 401 | F24: Referral | G24: {=OPS_10_Leasing_Funnel!E10} -> 19 | H24: {=MKT_16_Marketing_CPA!H15} -> 26.315789
A25: Apps Submitted | B25: 3 | C25: 18 | D25: 231 | F25: ILS (Apartments.com) | G25: {=OPS_10_Leasing_Funnel!E5} -> 18 | H25: {=MKT_16_Marketing_CPA!H10} -> 472.22222
A26: Leases Signed | B26: 2 | C26: 8 | D26: 104
A27: Move-Ins | B27: 1 | C27: 5 | D27: 19
A28: Move-Outs | B28: 0 | C28: 3 | D28: 12
A30: Data Sources: OPS_09, OPS_10, OPS_11, MKT_16 | Auto-refreshes daily at 6:00 AM

Sheet Portfolio_Summary
A1: PORTFOLIO SUMMARY DASHBOARD
A2: YTD Performance vs Plan | As of January 2026
A4: FINANCIAL PERFORMANCE | I4: EXECUTIVE SUMMARY
A5: Metric | B5: YTD Actual | C5: YTD Plan | D5: Variance $ | E5: Variance % | F5: Status | G5: Source | I5: Portfolio Occupancy | J5: {=B15} -> 0.95219124
A6: Total Revenue | B6: {=FIN_01_Investor_Pack!E7} -> 0 | C6: 52500000 | D6: =B6-C6 -> -52500000 | E6: =IF(C6=0,0,(B6-C6)/C6) -> -1 | F6: =IF(E6>=0,"✓","✗") -> ✗ | G6: FIN_01 | I6: Avg NER | J6: {=B16} -> 1814.3724
A7: Net Operating Income | B7: {=FIN_01_Investor_Pack!E21} -> 7715000 | C7: 32000000 | D7: =B7-C7 -> -24285000 | E7: =IF(C7=0,0,(B7-C7)/C7) -> -0.75890625 | F7: =IF(E7>=0,"✓","✗") -> ✗ | G7: FIN_01 | I7: NOI Margin | J7: {=B8} -> 0
A8: NOI Margin % | B8: =IF(B6=0,0,B7/B6) -> 0 | C8: 0.61 | D8: =B8-C8 -> -0.61 | E8: =IF(C8=0,0,(B8-C8)/C8) -> -1 | F8: =IF(E8>=0,"✓","✗") -> ✗ | G8: Calculated | I8: Same-Store Growth | J8: {=B10} -> 0.035689774
A9: FFO | B9: {=FIN_01_Investor_Pack!E34} -> 100000 | C9: 28000000 | D9: =B9-C9 -> -27900000 | E9: =IF(C9=0,0,(B9-C9)/C9) -> -0.99642857 | F9: =IF(E9>=0,"✓","✗") -> ✗ | G9: FIN_01 | I9: DSCR | J9: {=B11} -> 2.85
A10: Same-Store NOI Growth | B10: {=FIN_01_Investor_Pack!E58} -> 0.035689774 | C10: 0.025 | D10: =B10-C10 -> 0.010689774 | E10: =IF(C10=0,0,(B10-C10)/C10) -> 0.42759094 | F10: =IF(E10>=0,"✓","✗") -> ✓ | G10: FIN_01 | I10: Blended CPA | J10: {=B27} -> 230.76923
A11: Debt Service Coverage | B11: {=FIN_01_Investor_Pack!C63} -> 2.85 | C11: 1.4 | D11: =(B11-C11) -> 1.45 | E11: =IF(C11=0,0,(B11-C11)/C11) -> 1.0357143 | F11: =IF(E11>=0,"✓","✗") -> ✓ | G11: FIN_01 | I11: Renewal Rate | J11: {=B18} -> 0.72727273
I12: WO Avg Time | J12: {=B20} -> 19.392509
A13: OPERATIONS PERFORMANCE
A14: Metric | B14: YTD Actual | C14: YTD Plan | D14: Variance | E14: Variance % | F14: Status | G14: Source
A15: Occupancy % | B15: {=OPS_11_Occupancy_Mix!D12} -> 0.95219124 | C15: 0.94 | D15: =B15-C15 -> 0.012191235 | E15: =IF(C15=0,0,(B15-C15)/C15) -> 0.012969399 | F15: =IF(E15>=0,"✓","✗") -> ✓ | G15: OPS_11
A16: Avg NER | B16: {=OPS_11_Occupancy_Mix!G12} -> 1814.3724 | C16: 1780 | D16: =B16-C16 -> 34.372385 | E16: =IF(C16=0,0,(B16-C16)/C16) -> 0.019310329 | F16: =IF(E16>=0,"✓","✗") -> ✓ | G16: OPS_11
A17: Lead→Lease Conversion | B17: {=OPS_10_Leasing_Funnel!I12} -> 0.090356212 | C17: 0.08 | D17: =B17-C17 -> 0.010356212 | E17: =IF(C17=0,0,(B17-C17)/C17) -> 0.12945265 | F17: =IF(E17>=0,"✓","✗") -> ✓ | G17: OPS_10
A18: Renewal Rate | B18: {=OPS_12_Renewal_Retention!D10} -> 0.72727273 | C18: 0.7 | D18: =B18-C18 -> 0.027272727 | E18: =IF(C18=0,0,(B18-C18)/C18) -> 0.038961039 | F18: =IF(E18>=0,"✓","✗") -> ✓ | G18: OPS_12
A19: TTM Retention Rate | B19: {=OPS_12_Renewal_Retention!H13} -> 0.69583333 | C19: 0.68 | D19: =B19-C19 -> 0.015833333 | E19: =IF(C19=0,0,(B19-C19)/C19) -> 0.023284314 | F19: =IF(E19>=0,"✓","✗") -> ✓ | G19: OPS_12
A20: Avg WO Completion (hrs) | B20: {=OPS_14_Maintenance_WO!E11} -> 19.392509 | C20: 24 | D20: =B20-C20 -> -4.6074906 | E20: =IF(C20=0,0,(C20-B20)/C20) -> 0.19197878 | F20: =IF(E20>=0,"✓","✗") -> ✓ | G20: OPS_14
A21: Emergency SLA % | B21: {=OPS_14_Maintenance_WO!E15} -> 0.95238095 | C21: 0.95 | D21: =B21-C21 -> 0.0023809524 | E21: =IF(C21=0,0,(B21-C21)/C21) -> 0.0025062657 | F21: =IF(E21>=0,"✓","✗") -> ✓ | G21: OPS_14
A23: MARKETING PERFORMANCE
A24: Metric | B24: YTD Actual | C24: YTD Plan | D24: Variance | E24: Variance % | F24: Status | G24: Source
A25: Total Marketing Spend | B25: {=MKT_16_Marketing_CPA!B6} -> 24000 | C25: 28000 | D25: =B25-C25 -> -4000 | E25: =IF(C25=0,0,(C25-B25)/C25) -> 0.14285714 | F25: =IF(E25>=0,"✓","✗") -> ✓ | G25: MKT_16
A26: Cost Per Lead (CPL) | B26: {=MKT_16_Marketing_CPA!D6} -> 20.851434 | C26: 25 | D26: =B26-C26 -> -4.1485665 | E26: =IF(C26=0,0,(C26-B26)/C26) -> 0.16594266 | F26: =IF(E26>=0,"✓","✗") -> ✓ | G26: MKT_16
A27: Cost Per Acquisition (CPA) | B27: {=MKT_16_Marketing_CPA!H6} -> 230.76923 | C27: 300 | D27: =B27-C27 -> -69.230769 | E27: =IF(C27=0,0,(C27-B27)/C27) -> 0.23076923 | F27: =IF(E27>=0,"✓","✗") -> ✓ | G27: MKT_16
A28: Total Leads | B28: {=MKT_16_Marketing_CPA!C6} -> 1151 | C28: 1200 | D28: =B28-C28 -> -49 | E28: =IF(C28=0,0,(B28-C28)/C28) -> -0.040833333 | F28: =IF(E28>=0,"✓","✗") -> ✗ | G28: MKT_16
A29: Total Leases | B29: {=MKT_16_Marketing_CPA!G6} -> 104 | C29: 95 | D29: =B29-C29 -> 9 | E29: =IF(C29=0,0,(B29-C29)/C29) -> 0.094736842 | F29: =IF(E29>=0,"✓","✗") -> ✓ | G29: MKT_16
A30: LTV:CAC Ratio | B30: {=MKT_16_Marketing_CPA!B28} -> 311.31353 | C30: 3 | D30: =B30-C30 -> 308.31353 | E30: =IF(C30=0,0,(B30-C30)/C30) -> 102.77118 | F30: =IF(E30>=0,"✓","✗") -> ✓ | G30: MKT_16

Sheet Data_Validation
A1: DATA VALIDATION & UPLOAD MONITORING
A2: Daily CSV upload status, field mapping validation, and error tracking
A4: DAILY UPLOAD STATUS | J4: VALIDATION SUMMARY
A5: Template | B5: File Pattern | C5: Expected Frequency | D5: Last Upload | E5: Records | F5: Status | G5: Errors | H5: Action | J5: Templates Active | K5: 5
A6: RentRoll.csv | B6: *_RentRoll.csv | C6: Daily 6AM | D6: 2026-01-11 06:02 | E6: 251 | F6: ✓ OK | G6: 0 | H6: =_xlfn.IFERROR(IF(G6>0,"Review Errors",IF(F6="⚠ STALE","Check Source","—")),"—") -> — | J6: Total Fields Tracked | K6: =_xlfn.IFERROR(SUM(B14:B18),"—") -> 60
A7: LeasingActivity.csv | B7: *_Leasing.csv | C7: Daily 6PM | D7: 2026-01-10 18:15 | E7: 1 | F7: ⚠ STALE | G7: 0 | H7: =_xlfn.IFERROR(IF(G7>0,"Review Errors",IF(F7="⚠ STALE","Check Source","—")),"—") -> Check Source | J7: Fields Mapped | K7: =_xlfn.IFERROR(SUM(C14:C18),"—") -> 59
A8: Marketing.csv | B8: *_Marketing.csv | C8: Weekly Mon | D8: 2026-01-06 09:00 | E8: 7 | F8: ✓ OK | G8: 2 | H8: =_xlfn.IFERROR(IF(G8>0,"Review Errors",IF(F8="⚠ STALE","Check Source","—")),"—") -> Review Errors | J8: Overall Mapping % | K8: =_xlfn.IFERROR(IF(K6=0,0,K7/K6),"—") -> 0.98333333
A9: Maintenance.csv | B9: *_Maintenance.csv | C9: Daily 7AM | D9: 2026-01-11 07:05 | E9: 95 | F9: ✓ OK | G9: 1 | H9: =_xlfn.IFERROR(IF(G9>0,"Review Errors",IF(F9="⚠ STALE","Check Source","—")),"—") -> Review Errors | J9: Open Errors | K9: =_xlfn.IFERROR(SUM(G6:G10),"—") -> 3
A10: Financials.csv | B10: *_Financials.csv | C10: Monthly 5th | D10: 2026-01-05 08:30 | E10: 48 | F10: ✓ OK | G10: 0 | H10: =_xlfn.IFERROR(IF(G10>0,"Review Errors",IF(F10="⚠ STALE","Check Source","—")),"—") -> — | J10: Stale Uploads | K10: =_xlfn.IFERROR(COUNTIF(F6:F10,"⚠ STALE"),"—") -> 1
J11: Overall Quality Score | K11: =_xlfn.IFERROR(AVERAGE(C30:C34),"—") -> 0.9516
A12: FIELD MAPPING VALIDATION
A13: Template | B13: Required Fields | C13: Fields Mapped | D13: Missing | E13: Mapping % | F13: Status
A14: RentRoll.csv | B14: 16 | C14: 16 | D14: =_xlfn.IFERROR(B14-C14,"—") -> 0 | E14: =_xlfn.IFERROR(IF(B14=0,0,C14/B14),"—") -> 1 | F14: =_xlfn.IFERROR(IF(E14=1,"✓ Complete",IF(E14>=0.9,"⚠ Partial","✗ Missing")),"—") -> ✓ Complete
A15: LeasingActivity.csv | B15: 12 | C15: 12 | D15: =_xlfn.IFERROR(B15-C15,"—") -> 0 | E15: =_xlfn.IFERROR(IF(B15=0,0,C15/B15),"—") -> 1 | F15: =_xlfn.IFERROR(IF(E15=1,"✓ Complete",IF(E15>=0.9,"⚠ Partial","✗ Missing")),"—") -> ✓ Complete
A16: Marketing.csv | B16: 10 | C16: 10 | D16: =_xlfn.IFERROR(B16-C16,"—") -> 0 | E16: =_xlfn.IFERROR(IF(B16=0,0,C16/B16),"—") -> 1 | F16: =_xlfn.IFERROR(IF(E16=1,"✓ Complete",IF(E16>=0.9,"⚠ Partial","✗ Missing")),"—") -> ✓ Complete
A17: Maintenance.csv | B17: 8 | C17: 8 | D17: =_xlfn.IFERROR(B17-C17,"—") -> 0 | E17: =_xlfn.IFERROR(IF(B17=0,0,C17/B17),"—") -> 1 | F17: =_xlfn.IFERROR(IF(E17=1,"✓ Complete",IF(E17>=0.9,"⚠ Partial","✗ Missing")),"—") -> ✓ Complete
A18: Financials.csv | B18: 14 | C18: 13 | D18: =_xlfn.IFERROR(B18-C18,"—") -> 1 | E18: =_xlfn.IFERROR(IF(B18=0,0,C18/B18),"—") -> 0.92857143 | F18: =_xlfn.IFERROR(IF(E18=1,"✓ Complete",IF(E18>=0.9,"⚠ Partial","✗ Missing")),"—") -> ⚠ Partial
A20: ERROR LOG (LAST 7 DAYS)
A21: Date | B21: Template | C21: Error Type | D21: Field | E21: Count | F21: Severity | G21: Status | H21: Resolution
A22: 2026-01-11 | B22: Maintenance.csv | C22: Missing Value | D22: priority | E22: 1 | F22: Medium | G22: Open | H22: —
A23: 2026-01-10 | B23: Marketing.csv | C23: Invalid Format | D23: spend_amount | E23: 2 | F23: Low | G23: Resolved | H23: Corrected source
A24: 2026-01-09 | B24: RentRoll.csv | C24: Duplicate Key | D24: unit_id | E24: 3 | F24: High | G24: Resolved | H24: Deduped
A25: 2026-01-08 | B25: Financials.csv | C25: Out of Range | D25: revenue | E25: 1 | F25: Critical | G25: Resolved | H25: Data corrected
A26: 2026-01-07 | B26: LeasingActivity.csv | C26: Type Mismatch | D26: tours_completed | E26: 2 | F26: Medium | G26: Resolved | H26: Cast to INT
A28: DATA QUALITY SCORECARD
A29: Metric | B29: Target | C29: Actual | D29: Status | E29: Trend (7d)
A30: Completeness (all required fields) | B30: 1 | C30: 0.987 | D30: =_xlfn.IFERROR(IF(C30>=B30,"✓ PASS",IF(C30>=B30*0.95,"⚠ WARN","✗ FAIL")),"—") -> ⚠ WARN | E30: ↑ +0.2%
A31: Timeliness (on-time uploads) | B31: 1 | C31: 0.8 | D31: =_xlfn.IFERROR(IF(C31>=B31,"✓ PASS",IF(C31>=B31*0.95,"⚠ WARN","✗ FAIL")),"—") -> ✗ FAIL | E31: ↓ -20%
A32: Accuracy (no errors) | B32: 0.99 | C32: 0.978 | D32: =_xlfn.IFERROR(IF(C32>=B32,"✓ PASS",IF(C32>=B32*0.95,"⚠ WARN","✗ FAIL")),"—") -> ⚠ WARN | E32: ↑ +0.5%
A33: Consistency (format compliance) | B33: 1 | C33: 0.995 | D33: =_xlfn.IFERROR(IF(C33>=B33,"✓ PASS",IF(C33>=B33*0.95,"⚠ WARN","✗ FAIL")),"—") -> ⚠ WARN | E33: → 0%
A34: Uniqueness (no duplicates) | B34: 1 | C34: 0.998 | D34: =_xlfn.IFERROR(IF(C34>=B34,"✓ PASS",IF(C34>=B34*0.95,"⚠ WARN","✗ FAIL")),"—") -> ⚠ WARN | E34: ↑ +0.1%

Sheet Dashboard
A1: PATRY ENTERPRISE DASHBOARD
A2: Reports by Division | Click sheet tabs to navigate
A4: FINANCE & PORTFOLIO
A5: # | B5: Report | C5: Cadence | D5: Owner
A6: 1 | B6: Consolidated Financial Statements / Investor Pack | C6: Quarterly | D6: CFO
A7: 2 | B7: Monthly Portfolio NOI Pack | C7: Monthly | D7: Asset Mgr
A8: 3 | B8: Rent Roll & Lease Expirations | C8: Monthly+Daily | D8: Ops
A9: 4 | B9: Budget vs Actual / Variance Analysis | C9: Monthly | D9: Finance
A10: 5 | B10: 12-Month Cash Flow Forecast & Liquidity | C10: Monthly | D10: CFO
A11: 6 | B11: Capex Pipeline & Spend vs Budget | C11: Monthly | D11: Asset Mgr
A12: 7 | B12: Debt / Covenant Compliance | C12: Monthly | D12: CFO
A13: 8 | B13: Accounts Receivable & Bad Debt Rollup | C13: Monthly | D13: Finance
A15: LEASING / OPS / MARKETING
A16: # | B16: Report | C16: Cadence | D16: Owner
A17: 9 | B17: Property Leasing One-Pager | C17: Daily | D17: Ops Mgr
A18: 10 | B18: Leasing Funnel & Conversion Dashboard | C18: Daily | D18: Leasing Dir
A19: 11 | B19: Occupancy & Unit Mix / Floorplan Performance | C19: Monthly | D19: Asset Mgr
A20: 12 | B20: Renewal & Retention Report | C20: Monthly | D20: Ops Dir
A21: 13 | B21: Turnover & Make-Ready Cost Report | C21: Monthly | D21: Ops Dir
A22: 14 | B22: Maintenance Work Order & Backlog | C22: Daily | D22: Maint Dir
A23: 15 | B23: Resident Satisfaction & NPS | C23: Monthly | D23: Ops Dir
A24: 16 | B24: Marketing Performance & CPA Dashboard | C24: Daily | D24: Mkt Dir
A25: 17 | B25: Source-to-Lease Attribution | C25: Monthly | D25: Mkt Dir
A27: DEVELOPMENT / CONSTRUCTION
A28: # | B28: Report | C28: Cadence | D28: Owner
A29: 18 | B29: Project Status & Earned Value Report | C29: Weekly | D29: Dev Dir
A30: 19 | B30: Cost to Complete / Cashflow by Project | C30: Monthly | D30: Dev Dir
A31: 20 | B31: Entitlement & Risk Register | C31: Monthly | D31: Dev Dir
A33: CAPITAL MARKETS / GOVERNANCE / ESG
A34: # | B34: Report | C34: Cadence | D34: Owner
A35: 21 | B35: Investor Quarterly Pack & Asset Highlights | C35: Quarterly | D35: IR
A36: 22 | B36: ESG / Sustainability & Safety Report | C36: Quarterly | D36: ESG Mgr
A38: SUGGESTED ADDITIONAL REPORTS
A39: # | B39: Report | C39: Cadence | D39: Division
A40: 23 | B40: Tax & 1099 Reporting Pack | C40: Annual | D40: Finance
A41: 24 | B41: Insurance Renewal & Claims Tracker | C41: Quarterly | D41: Finance
A42: 25 | B42: Utility Cost Analysis & Benchmarking | C42: Monthly | D42: Finance
A43: 26 | B43: Competitor Market Survey | C43: Weekly | D43: Leasing
A44: 27 | B44: Amenity Utilization Report | C44: Monthly | D44: Ops
A45: 28 | B45: Lease Audit & Compliance | C45: Quarterly | D45: Ops
...

Sheet _TOC
A1: PATRY ENTERPRISE REPORTING SYSTEM - ARCHITECTURE SPECIFICATION
A2: Version 1.0 | Created: January 11, 2026 | 22 Reports | Daily Update Cadence
A4: TABLE OF CONTENTS
A6: # | B6: Sheet Name | C6: Report Title | D6: Category | E6: Cadence | F6: Owner | G6: Status
A7: 1 | B7: FIN_01_Investor_Pack | C7: Consolidated Financial Statements / Investor Pack | D7: Finance | E7: Quarterly | F7: CFO | G7: Template
A8: 2 | B8: FIN_02_NOI_Pack | C8: Monthly Portfolio NOI Pack | D8: Finance | E8: Monthly | F8: Asset Mgr | G8: Template
A9: 3 | B9: FIN_03_Rent_Roll | C9: Rent Roll & Lease Expirations | D9: Finance | E9: Monthly+Daily | F9: Ops | G9: Template
A10: 4 | B10: FIN_04_Budget_Variance | C10: Budget vs Actual / Variance Analysis | D10: Finance | E10: Monthly | F10: Finance | G10: Template
A11: 5 | B11: FIN_05_Cash_Flow | C11: 12-Month Cash Flow Forecast & Liquidity | D11: Finance | E11: Monthly | F11: CFO | G11: Template
A12: 6 | B12: FIN_06_Capex | C12: Capex Pipeline & Spend vs Budget | D12: Finance | E12: Monthly | F12: Asset Mgr | G12: Template
A13: 7 | B13: FIN_07_Debt_Covenant | C13: Debt / Covenant Compliance | D13: Finance | E13: Monthly | F13: CFO | G13: Template
A14: 8 | B14: FIN_08_AR_Bad_Debt | C14: Accounts Receivable & Bad Debt Rollup | D14: Finance | E14: Monthly | F14: Finance | G14: Template
A15: 9 | B15: OPS_09_Leasing_OnePager | C15: Property Leasing One-Pager | D15: Leasing | E15: Daily | F15: Ops Mgr | G15: Template
A16: 10 | B16: OPS_10_Leasing_Funnel | C16: Leasing Funnel & Conversion Dashboard | D16: Leasing | E16: Daily | F16: Leasing Dir | G16: Template
A17: 11 | B17: OPS_11_Occupancy_Mix | C17: Occupancy & Unit Mix / Floorplan Performance | D17: Leasing | E17: Monthly | F17: Asset Mgr | G17: Template
A18: 12 | B18: OPS_12_Renewal_Retention | C18: Renewal & Retention Report | D18: Leasing | E18: Monthly | F18: Ops Dir | G18: Template
... A28: 22 | B28: ESG_22_Sustainability | C28: ESG / Sustainability & Safety Report | D28: ESG | E28: Quarterly | F28: ESG Mgr | G28: Template
A31: SYSTEM SHEETS
A33: SYS | B33: _CSV_Templates | C33: CSV Upload Templates & Schemas | D33: Data Ingestion | E33: — | F33: Admin | G33: Template
A34: SYS | B34: _KPI_Dictionary | C34: KPI Definitions & Business Rules | D34: Reference | E34: — | F34: Admin | G34: Template
A35: SYS | B35: _Alert_Rules | C35: Alert Thresholds & Notification Rules | D35: Alerting | E35: — | F35: Admin | G35: Template
A36: SYS | B36: _Access_Matrix | C36: Role-Based Access & Distribution | D36: Governance | E36: — | F36: Admin | G36: Template
A37: SYS | B37: _Validation_Log | C37: Data Validation & Reconciliation Log | D37: Quality | E37: Daily | F37: System | G37: Template

Sheet _CSV_Templates
A1: CSV UPLOAD TEMPLATES & DATA SCHEMAS
A2: File naming: YYYYMMDD_<PropertyID>_<DataType>.csv | Example: 20260115_150Marketplace_Leasing.csv
A4: TEMPLATE 1: RentRoll.csv
A5: Field Name | B5: Data Type | C5: Required | D5: Validation Rule | E5: Example | F5: Notes
A6: property_id | B6: STRING | C6: Yes | D6: Non-empty, valid property code | E6: 150MKT | F6: Unique property identifier
A7: property_name | B7: STRING | C7: Yes | D7: Non-empty | E7: 150 Marketplace | F7: Full property name
A8: unit_id | B8: STRING | C8: Yes | D8: Unique per property | E8: 101 | F8: Unit number
A9: unit_type | B9: STRING | C9: Yes | D9: Studio|1BR|1BR+Den|2BR|3BR | E9: 1BR+Den | F9: Floorplan category
A10: sqft | B10: INTEGER | C10: Yes | D10: >0 and <10000 | E10: 875 | F10: Unit square footage
A11: floor | B11: INTEGER | C11: No | D11: >=0 | E11: 5 | F11: Floor number
A12: status | B12: STRING | C12: Yes | D12: Leased|Available|Notice|Down|Model | E12: Leased | F12: Current unit status
A13: lease_start_date | B13: DATE | C13: Cond | D13: YYYY-MM-DD, if Leased | E13: 2025-06-01 | F13: Current lease start
A14: lease_end_date | B14: DATE | C14: Cond | D14: YYYY-MM-DD, >= lease_start | E14: 2026-05-31 | F14: Current lease end
A15: contract_rent | B15: DECIMAL | C15: Cond | D15: >0 if Leased | E15: 2350 | F15: Monthly contract rent
A16: market_rent | B16: DECIMAL | C16: Yes | D16: >0 | E16: 2495 | F16: Current market/asking rent
A17: concession_monthly | B17: DECIMAL | C17: No | D17: >=0 | E17: 100 | F17: Monthly concession amount
A18: net_effective_rent | B18: DECIMAL | C18: Calc | D18: contract-(concession/term) | E18: 2266.67 | F18: NER calculation
A19: resident_id | B19: STRING | C19: Cond | D19: If Leased | E19: RES-45678 | F19: Resident identifier
A20: move_in_date | B20: DATE | C20: Cond | D20: YYYY-MM-DD if occupied | E20: 2025-06-15 | F20: Actual move-in
A21: timestamp | B21: DATETIME | C21: Yes | D21: ISO 8601 | E21: 2026-01-11T09:00:00 | F21: Extraction time
A23: TEMPLATE 2: LeasingActivity.csv
A24: Field Name | B24: Data Type | C24: Required | D24: Validation Rule | E24: Example | F24: Notes
A25: property_id | B25: STRING | C25: Yes | D25: Valid property code | E25: 150MKT | F25: Property identifier
A26: report_date | B26: DATE | C26: Yes | D26: YYYY-MM-DD | E26: 2026-01-11 | F26: Activity date
A27: new_leads | B27: INTEGER | C27: Yes | D27: >=0 | E27: 12 | F27: Guest cards created
A28: leads_contacted_1hr | B28: INTEGER | C28: Yes | D28: <=new_leads | E28: 10 | F28: Contacted within 1hr
A29: tours_scheduled | B29: INTEGER | C29: Yes | D29: >=0 | E29: 8 | F29: Tours scheduled
A30: tours_completed | B30: INTEGER | C30: Yes | D30: >=0 | E30: 6 | F30: Tours completed
A31: apps_submitted | B31: INTEGER | C31: Yes | D31: >=0 | E31: 3 | F31: Apps submitted
A32: apps_approved | B32: INTEGER | C32: Yes | D32: >=0 | E32: 2 | F32: Apps approved
A33: leases_signed | B33: INTEGER | C33: Yes | D33: >=0 | E33: 1 | F33: Leases executed
A34: followups_due | B34: INTEGER | C34: Yes | D34: >=0 | E34: 25 | F34: Follow-ups due
A35: followups_completed | B35: INTEGER | C35: Yes | D35: >=0 | E35: 23 | F35: Follow-ups done
A36: timestamp | B36: DATETIME | C36: Yes | D36: ISO 8601 | E36: 2026-01-11T18:00:00 | F36: Extraction time
A38: TEMPLATE 3: Marketing.csv
A39: Field Name | B39: Data Type | C39: Required | D39: Validation Rule | E39: Example | F39: Notes
A40: property_id | B40: STRING | C40: Yes | D40: Valid property code | E40: 150MKT | F40: Property identifier
A41: report_date | B41: DATE | C41: Yes | D41: YYYY-MM-DD | E41: 2026-01-11 | F41: Campaign date
A42: channel | B42: STRING | C42: Yes | D42: ILS|PPC|Social|Direct|Referral | E42: ILS | F42: Marketing channel
A43: campaign_id | B43: STRING | C43: No | D43: Valid campaign code | E43: APT-Q1-2026 | F43: Campaign identifier
...

Sheet _KPI_Dictionary
A1: KPI DEFINITIONS & BUSINESS RULES
A2: Standard definitions for portfolio-wide consistency. Do not modify without Ops/Finance approval.
A4: CORE FINANCIAL KPIs
A5: KPI Name | B5: Definition | C5: Formula | D5: Data Source | E5: Cadence | F5: Owner | G5: Yellow Threshold | H5: Red Threshold | I5: Excel Formula | J5: Example Calc | K5: Units
A6: NOI | B6: Net Operating Income = Revenue - Operating Expenses | C6: Revenue - OpEx | D6: Financials.csv | E6: Monthly | F6: Asset Mgr | G6: <Budget -5% | H6: <Budget -10% | I6: =SUM(Revenue)-SUM(OpEx) -> #NAME? | J6: 500000-350000=150000 | K6: $
A7: Same-Store NOI | B7: NOI for properties owned >12 months, YoY comparison | C7: (Current NOI - Prior NOI) / Prior NOI | D7: Financials.csv | E7: Monthly | F7: Asset Mgr | G7: YoY <2% | H7: YoY <0% | I7: =(CurrentNOI-PriorNOI)/PriorNOI -> #NAME? | J7: (150000-140000)/140000=7.1% | K7: %
A8: FFO | B8: Funds From Operations (REIT standard) | C8: Net Income + D&A - Gains on Sales | D8: Financials.csv | E8: Quarterly | F8: CFO | G8: <Guidance -5% | H8: <Guidance -10% | I8: =NetIncome+Depreciation-GainOnSale -> #NAME? | J8: 100000+50000-10000=140000 | K8: $
A9: DSCR | B9: Debt Service Coverage Ratio | C9: NOI / Total Debt Service | D9: Financials.csv | E9: Monthly | F9: CFO | G9: <1.30x | H9: <1.20x | I9: =NOI/AnnualDebtService -> #NAME? | J9: 150000/100000=1.50x | K9: x
A10: Leverage Ratio | B10: Total Debt / Total Assets | C10: Debt / Assets | D10: Financials.csv | E10: Monthly | F10: CFO | G10: >60% | H10: >65% | I10: =TotalDebt/TotalAssets -> #NAME? | J10: 60000000/100000000=60% | K10: %
A11: Delinquency Rate | B11: Past due rent / Total rent billed | C11: Delinquent $ / Billed $ | D11: AR Report | E11: Monthly | F11: Finance | G11: >3% | H11: >5% | I11: =SUMIF(AR,">0")/TotalBilled -> #NAME? | J11: 15000/500000=3% | K11: %
A12: Bad Debt % | B12: Write-offs / Revenue | C12: Write-offs / Revenue | D12: Financials.csv | E12: Monthly | F12: Finance | G12: >1% | H12: >2% | I12: =WriteOffs/Revenue -> #NAME? | J12: 5000/500000=1% | K12: %
A14: LEASING & OCCUPANCY KPIs
A15: KPI Name | B15: Definition | C15: Formula | D15: Data Source | E15: Cadence | F15: Owner | G15: Yellow Threshold | H15: Red Threshold | I15: Excel Formula | J15: Example Calc | K15: Units
A16: Physical Occupancy % | B16: Occupied units / Total units | C16: Occupied / Total | D16: RentRoll.csv | E16: Daily | F16: Ops Mgr | G16: <95% | H16: <92% | I16: '=COUNTIF(Status,"Leased")/COUNTA(UnitID) | J16: 275/357=77.0% | K16: %
A17: Economic Occupancy % | B17: Collected rent / Potential rent | C17: Collected / (Units × Market) | D17: RentRoll.csv | E17: Monthly | F17: Asset Mgr | G17: <90% | H17: <85% | I17: '=SUM(CollectedRent)/SUM(MarketRent) | J17: 450000/500000=90% | K17: %
A18: Net Effective Rent (NER) | B18: Contract rent - (Concessions / Lease Term) | C18: (Contract - Concession) / Term | D18: RentRoll.csv | E18: Daily | F18: Leasing | G18: <Market -5% | H18: <Market -10% | I18: '=ContractRent-(Concession/LeaseTerm) | J18: 2400-(600/12)=2350 | K18: $
A19: Lead-to-Tour % | B19: Tours completed / New leads | C19: Tours / Leads | D19: LeasingActivity.csv | E19: Daily | F19: Leasing Dir | G19: <40% | H19: <30% | I19: '=ToursCompleted/NewLeads | J19: 6/15=40% | K19: %
A20: Tour-to-Lease % | B20: Leases signed / Tours completed | C20: Leases / Tours | D20: LeasingActivity.csv | E20: Daily | F20: Leasing Dir | G20: <25% | H20: <20% | I20: '=LeasesSigned/ToursCompleted | J20: 2/6=33% | K20: %
A21: Lead-to-Lease % | B21: Leases signed / New leads | C21: Leases / Leads | D21: LeasingActivity.csv | E21: Daily | F21: Leasing Dir | G21: <15% | H21: <10% | I21: '=LeasesSigned/NewLeads | J21: 2/15=13% | K21: %
A22: Renewal Rate | B22: Renewals / Expiring leases | C22: Renewed / Expiring | D22: RentRoll.csv | E22: Monthly | F22: Ops Dir | G22: <55% | H22: <50% | I22: '=Renewals/ExpiringLeases | J22: 45/80=56% | K22: %
A23: Days on Market | B23: Avg days unit vacant before lease | C23: Avg(Lease Date - Vacant Date) | D23: RentRoll.csv | E23: Weekly | F23: Leasing | G23: >21 days | H23: >30 days | I23: '=AVERAGE(LeaseDate-VacantDate) | J23: AVG(14,21,7)=14 | K23: days
A24: Follow-up Completion % | B24: Completed follow-ups / Due follow-ups | C24: Completed / Due | D24: LeasingActivity.csv | E24: Daily | F24: Leasing Mgr | G24: <95% | H24: <90% | I24: '=FollowupsCompleted/FollowupsDue | J24: 23/25=92% | K24: %
A26: MARKETING KPIs
A27: KPI Name | B27: Definition | C27: Formula | D27: Data Source | E27: Cadence | F27: Owner | G27: Yellow Threshold | H27: Red Threshold | I27: Excel Formula | J27: Example Calc | K27: Units
A28: Cost Per Lead (CPL) | B28: Marketing spend / Leads generated | C28: Spend / Leads | D28: Marketing.csv | E28: Weekly | F28: Mkt Dir | G28: >$75 | H28: >$100 | I28: '=MarketingSpend/Leads | J28: 1500/20=$75 | K28: $
A29: Cost Per Tour (CPT) | B29: Marketing spend / Tours from marketing | C29: Spend / Tours | D29: Marketing.csv | E29: Weekly | F29: Mkt Dir | G29: >$150 | H29: >$200 | I29: '=MarketingSpend/Tours | J29: 1500/10=$150 | K29: $
A30: Cost Per Acquisition (CPA) | B30: Marketing spend / Leases signed | C30: Spend / Leases | D30: Marketing.csv | E30: Weekly | F30: Mkt Dir | G30: >1 mo rent | H30: >1.5 mo rent | I30: '=MarketingSpend/Leases | J30: 1500/3=$500 | K30: $
A31: Customer Acquisition Cost (CAC) | B31: Total acquisition cost per new resident | C31: (Mkt + Leasing Ops) / Leases | D31: Marketing.csv | E31: Monthly | F31: Mkt Dir | G31: >$2000 | H31: >$3000 | I31: '=(MktSpend+LeasingCost)/Leases | J31: (1500+500)/3=$667 | K31: $
A32: LTV:CAC Ratio | B32: Lifetime Value / Customer Acquisition Cost | C32: LTV / CAC | D32: Calculated | E32: Monthly | F32: Mkt Dir | G32: <3:1 | H32: <2:1 | I32: '=LTV/CAC | J32: 7200/667=10.8x | K32: ratio
A33: Click-Through Rate (CTR) | B33: Clicks / Impressions | C33: Clicks / Impressions | D33: Marketing.csv | E33: Weekly | F33: Mkt Dir | G33: <1.5% | H33: <1% | I33: '=Clicks/Impressions | J33: 450/30000=1.5% | K33: %
A34: Conversion Rate (Web) | B34: Leads / Sessions | C34: Leads / Sessions | D34: GA4 | E34: Weekly | F34: Mkt Dir | G34: <3% | H34: <2% | I34: '=Leads/Sessions | J34: 20/800=2.5% | K34: %
A36: OPERATIONS & MAINTENANCE KPIs
A37: KPI Name | B37: Definition | C37: Formula | D37: Data Source | E37: Cadence | F37: Owner | G37: Yellow Threshold | H37: Red Threshold | I37: Excel Formula | J37: Example Calc | K37: Units
